2025-10-20 18:02:50,234 [WARNING] Could not import/register tasks blueprint: No module named 'db'
2025-10-20 20:38:23,299 [WARNING] Could not import/register tasks blueprint: No module named 'db'
2025-10-20 21:42:28,245 [INFO] Registered tasks blueprint at /api/v1/tasks
2025-10-20 21:42:47,977 [WARNING] Could not import/register tasks blueprint: cannot import name 'bp' from partially initialized module 'backend.tasks.routes' (most likely due to a circular import) (C:\Users\dshan\portility\backend\tasks\routes.py)
2025-10-20 21:42:47,988 [INFO] Registered tasks blueprint at /api/v1/tasks
2025-10-20 21:42:49,697 [WARNING] Could not import/register tasks blueprint: cannot import name 'bp' from partially initialized module 'backend.tasks.routes' (most likely due to a circular import) (C:\Users\dshan\portility\backend\tasks\routes.py)
2025-10-20 21:42:49,708 [INFO] Registered tasks blueprint at /api/v1/tasks
2025-10-20 21:42:56,889 [INFO] GET / - from 127.0.0.1
2025-10-20 21:42:59,403 [INFO] GET /favicon.ico - from 127.0.0.1
2025-10-20 21:43:48,960 [INFO] GET /api/v1/tasks/ - from 127.0.0.1
2025-10-20 21:43:48,975 [ERROR] Unhandled exception: (sqlite3.OperationalError) no such table: tasks
[SQL: SELECT tasks.id AS tasks_id, tasks.title AS tasks_title, tasks.description AS tasks_description, tasks.status AS tasks_status, tasks.due_date AS tasks_due_date, tasks.created_at AS tasks_created_at, tasks.updated_at AS tasks_updated_at 
FROM tasks ORDER BY tasks.created_at DESC]
(Background on this error at: https://sqlalche.me/e/20/e3q8)
Traceback (most recent call last):
  File "C:\Users\dshan\portility\backend\venv\Lib\site-packages\sqlalchemy\engine\base.py", line 1967, in _exec_single_context
    self.dialect.do_execute(
    ~~~~~~~~~~~~~~~~~~~~~~~^
        cursor, str_statement, effective_parameters, context
        ^^^^^^^^^^^^^^^^^^^^^^^^^^^^^^^^^^^^^^^^^^^^^^^^^^^^
    )
    ^
  File "C:\Users\dshan\portility\backend\venv\Lib\site-packages\sqlalchemy\engine\default.py", line 951, in do_execute
    cursor.execute(statement, parameters)
    ~~~~~~~~~~~~~~^^^^^^^^^^^^^^^^^^^^^^^
sqlite3.OperationalError: no such table: tasks

The above exception was the direct cause of the following exception:

Traceback (most recent call last):
  File "C:\Users\dshan\portility\backend\venv\Lib\site-packages\flask\app.py", line 917, in full_dispatch_request
    rv = self.dispatch_request()
  File "C:\Users\dshan\portility\backend\venv\Lib\site-packages\flask\app.py", line 902, in dispatch_request
    return self.ensure_sync(self.view_functions[rule.endpoint])(**view_args)  # type: ignore[no-any-return]
           ~~~~~~~~~~~~~~~~~~~~~~~~~~~~~~~~~~~~~~~~~~~~~~~~~~~~^^^^^^^^^^^^^
  File "C:\Users\dshan\portility\backend\tasks\routes.py", line 12, in api_get_tasks
    all_tasks = get_tasks()
  File "C:\Users\dshan\portility\backend\tasks_store_sql.py", line 7, in get_tasks
    rows = Task.query.order_by(Task.created_at.desc()).all()
  File "C:\Users\dshan\portility\backend\venv\Lib\site-packages\sqlalchemy\orm\query.py", line 2704, in all
    return self._iter().all()  # type: ignore
           ~~~~~~~~~~^^
  File "C:\Users\dshan\portility\backend\venv\Lib\site-packages\sqlalchemy\orm\query.py", line 2857, in _iter
    result: Union[ScalarResult[_T], Result[_T]] = self.session.execute(
                                                  ~~~~~~~~~~~~~~~~~~~~^
        statement,
        ^^^^^^^^^^
        params,
        ^^^^^^^
        execution_options={"_sa_orm_load_options": self.load_options},
        ^^^^^^^^^^^^^^^^^^^^^^^^^^^^^^^^^^^^^^^^^^^^^^^^^^^^^^^^^^^^^^
    )
    ^
  File "C:\Users\dshan\portility\backend\venv\Lib\site-packages\sqlalchemy\orm\session.py", line 2351, in execute
    return self._execute_internal(
           ~~~~~~~~~~~~~~~~~~~~~~^
        statement,
        ^^^^^^^^^^
    ...<4 lines>...
        _add_event=_add_event,
        ^^^^^^^^^^^^^^^^^^^^^^
    )
    ^
  File "C:\Users\dshan\portility\backend\venv\Lib\site-packages\sqlalchemy\orm\session.py", line 2249, in _execute_internal
    result: Result[Any] = compile_state_cls.orm_execute_statement(
                          ~~~~~~~~~~~~~~~~~~~~~~~~~~~~~~~~~~~~~~~^
        self,
        ^^^^^
    ...<4 lines>...
        conn,
        ^^^^^
    )
    ^
  File "C:\Users\dshan\portility\backend\venv\Lib\site-packages\sqlalchemy\orm\context.py", line 306, in orm_execute_statement
    result = conn.execute(
        statement, params or {}, execution_options=execution_options
    )
  File "C:\Users\dshan\portility\backend\venv\Lib\site-packages\sqlalchemy\engine\base.py", line 1419, in execute
    return meth(
        self,
        distilled_parameters,
        execution_options or NO_OPTIONS,
    )
  File "C:\Users\dshan\portility\backend\venv\Lib\site-packages\sqlalchemy\sql\elements.py", line 526, in _execute_on_connection
    return connection._execute_clauseelement(
           ~~~~~~~~~~~~~~~~~~~~~~~~~~~~~~~~~^
        self, distilled_params, execution_options
        ^^^^^^^^^^^^^^^^^^^^^^^^^^^^^^^^^^^^^^^^^
    )
    ^
  File "C:\Users\dshan\portility\backend\venv\Lib\site-packages\sqlalchemy\engine\base.py", line 1641, in _execute_clauseelement
    ret = self._execute_context(
        dialect,
    ...<8 lines>...
        cache_hit=cache_hit,
    )
  File "C:\Users\dshan\portility\backend\venv\Lib\site-packages\sqlalchemy\engine\base.py", line 1846, in _execute_context
    return self._exec_single_context(
           ~~~~~~~~~~~~~~~~~~~~~~~~~^
        dialect, context, statement, parameters
        ^^^^^^^^^^^^^^^^^^^^^^^^^^^^^^^^^^^^^^^
    )
    ^
  File "C:\Users\dshan\portility\backend\venv\Lib\site-packages\sqlalchemy\engine\base.py", line 1986, in _exec_single_context
    self._handle_dbapi_exception(
    ~~~~~~~~~~~~~~~~~~~~~~~~~~~~^
        e, str_statement, effective_parameters, cursor, context
        ^^^^^^^^^^^^^^^^^^^^^^^^^^^^^^^^^^^^^^^^^^^^^^^^^^^^^^^
    )
    ^
  File "C:\Users\dshan\portility\backend\venv\Lib\site-packages\sqlalchemy\engine\base.py", line 2355, in _handle_dbapi_exception
    raise sqlalchemy_exception.with_traceback(exc_info[2]) from e
  File "C:\Users\dshan\portility\backend\venv\Lib\site-packages\sqlalchemy\engine\base.py", line 1967, in _exec_single_context
    self.dialect.do_execute(
    ~~~~~~~~~~~~~~~~~~~~~~~^
        cursor, str_statement, effective_parameters, context
        ^^^^^^^^^^^^^^^^^^^^^^^^^^^^^^^^^^^^^^^^^^^^^^^^^^^^
    )
    ^
  File "C:\Users\dshan\portility\backend\venv\Lib\site-packages\sqlalchemy\engine\default.py", line 951, in do_execute
    cursor.execute(statement, parameters)
    ~~~~~~~~~~~~~~^^^^^^^^^^^^^^^^^^^^^^^
sqlalchemy.exc.OperationalError: (sqlite3.OperationalError) no such table: tasks
[SQL: SELECT tasks.id AS tasks_id, tasks.title AS tasks_title, tasks.description AS tasks_description, tasks.status AS tasks_status, tasks.due_date AS tasks_due_date, tasks.created_at AS tasks_created_at, tasks.updated_at AS tasks_updated_at 
FROM tasks ORDER BY tasks.created_at DESC]
(Background on this error at: https://sqlalche.me/e/20/e3q8)
2025-10-20 21:43:49,259 [INFO] GET /api/v1/tasks/ - from 127.0.0.1
2025-10-20 21:43:49,268 [ERROR] Unhandled exception: (sqlite3.OperationalError) no such table: tasks
[SQL: SELECT tasks.id AS tasks_id, tasks.title AS tasks_title, tasks.description AS tasks_description, tasks.status AS tasks_status, tasks.due_date AS tasks_due_date, tasks.created_at AS tasks_created_at, tasks.updated_at AS tasks_updated_at 
FROM tasks ORDER BY tasks.created_at DESC]
(Background on this error at: https://sqlalche.me/e/20/e3q8)
Traceback (most recent call last):
  File "C:\Users\dshan\portility\backend\venv\Lib\site-packages\sqlalchemy\engine\base.py", line 1967, in _exec_single_context
    self.dialect.do_execute(
    ~~~~~~~~~~~~~~~~~~~~~~~^
        cursor, str_statement, effective_parameters, context
        ^^^^^^^^^^^^^^^^^^^^^^^^^^^^^^^^^^^^^^^^^^^^^^^^^^^^
    )
    ^
  File "C:\Users\dshan\portility\backend\venv\Lib\site-packages\sqlalchemy\engine\default.py", line 951, in do_execute
    cursor.execute(statement, parameters)
    ~~~~~~~~~~~~~~^^^^^^^^^^^^^^^^^^^^^^^
sqlite3.OperationalError: no such table: tasks

The above exception was the direct cause of the following exception:

Traceback (most recent call last):
  File "C:\Users\dshan\portility\backend\venv\Lib\site-packages\flask\app.py", line 917, in full_dispatch_request
    rv = self.dispatch_request()
  File "C:\Users\dshan\portility\backend\venv\Lib\site-packages\flask\app.py", line 902, in dispatch_request
    return self.ensure_sync(self.view_functions[rule.endpoint])(**view_args)  # type: ignore[no-any-return]
           ~~~~~~~~~~~~~~~~~~~~~~~~~~~~~~~~~~~~~~~~~~~~~~~~~~~~^^^^^^^^^^^^^
  File "C:\Users\dshan\portility\backend\tasks\routes.py", line 12, in api_get_tasks
    all_tasks = get_tasks()
  File "C:\Users\dshan\portility\backend\tasks_store_sql.py", line 7, in get_tasks
    rows = Task.query.order_by(Task.created_at.desc()).all()
  File "C:\Users\dshan\portility\backend\venv\Lib\site-packages\sqlalchemy\orm\query.py", line 2704, in all
    return self._iter().all()  # type: ignore
           ~~~~~~~~~~^^
  File "C:\Users\dshan\portility\backend\venv\Lib\site-packages\sqlalchemy\orm\query.py", line 2857, in _iter
    result: Union[ScalarResult[_T], Result[_T]] = self.session.execute(
                                                  ~~~~~~~~~~~~~~~~~~~~^
        statement,
        ^^^^^^^^^^
        params,
        ^^^^^^^
        execution_options={"_sa_orm_load_options": self.load_options},
        ^^^^^^^^^^^^^^^^^^^^^^^^^^^^^^^^^^^^^^^^^^^^^^^^^^^^^^^^^^^^^^
    )
    ^
  File "C:\Users\dshan\portility\backend\venv\Lib\site-packages\sqlalchemy\orm\session.py", line 2351, in execute
    return self._execute_internal(
           ~~~~~~~~~~~~~~~~~~~~~~^
        statement,
        ^^^^^^^^^^
    ...<4 lines>...
        _add_event=_add_event,
        ^^^^^^^^^^^^^^^^^^^^^^
    )
    ^
  File "C:\Users\dshan\portility\backend\venv\Lib\site-packages\sqlalchemy\orm\session.py", line 2249, in _execute_internal
    result: Result[Any] = compile_state_cls.orm_execute_statement(
                          ~~~~~~~~~~~~~~~~~~~~~~~~~~~~~~~~~~~~~~~^
        self,
        ^^^^^
    ...<4 lines>...
        conn,
        ^^^^^
    )
    ^
  File "C:\Users\dshan\portility\backend\venv\Lib\site-packages\sqlalchemy\orm\context.py", line 306, in orm_execute_statement
    result = conn.execute(
        statement, params or {}, execution_options=execution_options
    )
  File "C:\Users\dshan\portility\backend\venv\Lib\site-packages\sqlalchemy\engine\base.py", line 1419, in execute
    return meth(
        self,
        distilled_parameters,
        execution_options or NO_OPTIONS,
    )
  File "C:\Users\dshan\portility\backend\venv\Lib\site-packages\sqlalchemy\sql\elements.py", line 526, in _execute_on_connection
    return connection._execute_clauseelement(
           ~~~~~~~~~~~~~~~~~~~~~~~~~~~~~~~~~^
        self, distilled_params, execution_options
        ^^^^^^^^^^^^^^^^^^^^^^^^^^^^^^^^^^^^^^^^^
    )
    ^
  File "C:\Users\dshan\portility\backend\venv\Lib\site-packages\sqlalchemy\engine\base.py", line 1641, in _execute_clauseelement
    ret = self._execute_context(
        dialect,
    ...<8 lines>...
        cache_hit=cache_hit,
    )
  File "C:\Users\dshan\portility\backend\venv\Lib\site-packages\sqlalchemy\engine\base.py", line 1846, in _execute_context
    return self._exec_single_context(
           ~~~~~~~~~~~~~~~~~~~~~~~~~^
        dialect, context, statement, parameters
        ^^^^^^^^^^^^^^^^^^^^^^^^^^^^^^^^^^^^^^^
    )
    ^
  File "C:\Users\dshan\portility\backend\venv\Lib\site-packages\sqlalchemy\engine\base.py", line 1986, in _exec_single_context
    self._handle_dbapi_exception(
    ~~~~~~~~~~~~~~~~~~~~~~~~~~~~^
        e, str_statement, effective_parameters, cursor, context
        ^^^^^^^^^^^^^^^^^^^^^^^^^^^^^^^^^^^^^^^^^^^^^^^^^^^^^^^
    )
    ^
  File "C:\Users\dshan\portility\backend\venv\Lib\site-packages\sqlalchemy\engine\base.py", line 2355, in _handle_dbapi_exception
    raise sqlalchemy_exception.with_traceback(exc_info[2]) from e
  File "C:\Users\dshan\portility\backend\venv\Lib\site-packages\sqlalchemy\engine\base.py", line 1967, in _exec_single_context
    self.dialect.do_execute(
    ~~~~~~~~~~~~~~~~~~~~~~~^
        cursor, str_statement, effective_parameters, context
        ^^^^^^^^^^^^^^^^^^^^^^^^^^^^^^^^^^^^^^^^^^^^^^^^^^^^
    )
    ^
  File "C:\Users\dshan\portility\backend\venv\Lib\site-packages\sqlalchemy\engine\default.py", line 951, in do_execute
    cursor.execute(statement, parameters)
    ~~~~~~~~~~~~~~^^^^^^^^^^^^^^^^^^^^^^^
sqlalchemy.exc.OperationalError: (sqlite3.OperationalError) no such table: tasks
[SQL: SELECT tasks.id AS tasks_id, tasks.title AS tasks_title, tasks.description AS tasks_description, tasks.status AS tasks_status, tasks.due_date AS tasks_due_date, tasks.created_at AS tasks_created_at, tasks.updated_at AS tasks_updated_at 
FROM tasks ORDER BY tasks.created_at DESC]
(Background on this error at: https://sqlalche.me/e/20/e3q8)
2025-10-20 21:43:49,302 [INFO] GET /api/v1/tasks/ - from 127.0.0.1
2025-10-20 21:43:49,322 [ERROR] Unhandled exception: (sqlite3.OperationalError) no such table: tasks
[SQL: SELECT tasks.id AS tasks_id, tasks.title AS tasks_title, tasks.description AS tasks_description, tasks.status AS tasks_status, tasks.due_date AS tasks_due_date, tasks.created_at AS tasks_created_at, tasks.updated_at AS tasks_updated_at 
FROM tasks ORDER BY tasks.created_at DESC]
(Background on this error at: https://sqlalche.me/e/20/e3q8)
Traceback (most recent call last):
  File "C:\Users\dshan\portility\backend\venv\Lib\site-packages\sqlalchemy\engine\base.py", line 1967, in _exec_single_context
    self.dialect.do_execute(
    ~~~~~~~~~~~~~~~~~~~~~~~^
        cursor, str_statement, effective_parameters, context
        ^^^^^^^^^^^^^^^^^^^^^^^^^^^^^^^^^^^^^^^^^^^^^^^^^^^^
    )
    ^
  File "C:\Users\dshan\portility\backend\venv\Lib\site-packages\sqlalchemy\engine\default.py", line 951, in do_execute
    cursor.execute(statement, parameters)
    ~~~~~~~~~~~~~~^^^^^^^^^^^^^^^^^^^^^^^
sqlite3.OperationalError: no such table: tasks

The above exception was the direct cause of the following exception:

Traceback (most recent call last):
  File "C:\Users\dshan\portility\backend\venv\Lib\site-packages\flask\app.py", line 917, in full_dispatch_request
    rv = self.dispatch_request()
  File "C:\Users\dshan\portility\backend\venv\Lib\site-packages\flask\app.py", line 902, in dispatch_request
    return self.ensure_sync(self.view_functions[rule.endpoint])(**view_args)  # type: ignore[no-any-return]
           ~~~~~~~~~~~~~~~~~~~~~~~~~~~~~~~~~~~~~~~~~~~~~~~~~~~~^^^^^^^^^^^^^
  File "C:\Users\dshan\portility\backend\tasks\routes.py", line 12, in api_get_tasks
    all_tasks = get_tasks()
  File "C:\Users\dshan\portility\backend\tasks_store_sql.py", line 7, in get_tasks
    rows = Task.query.order_by(Task.created_at.desc()).all()
  File "C:\Users\dshan\portility\backend\venv\Lib\site-packages\sqlalchemy\orm\query.py", line 2704, in all
    return self._iter().all()  # type: ignore
           ~~~~~~~~~~^^
  File "C:\Users\dshan\portility\backend\venv\Lib\site-packages\sqlalchemy\orm\query.py", line 2857, in _iter
    result: Union[ScalarResult[_T], Result[_T]] = self.session.execute(
                                                  ~~~~~~~~~~~~~~~~~~~~^
        statement,
        ^^^^^^^^^^
        params,
        ^^^^^^^
        execution_options={"_sa_orm_load_options": self.load_options},
        ^^^^^^^^^^^^^^^^^^^^^^^^^^^^^^^^^^^^^^^^^^^^^^^^^^^^^^^^^^^^^^
    )
    ^
  File "C:\Users\dshan\portility\backend\venv\Lib\site-packages\sqlalchemy\orm\session.py", line 2351, in execute
    return self._execute_internal(
           ~~~~~~~~~~~~~~~~~~~~~~^
        statement,
        ^^^^^^^^^^
    ...<4 lines>...
        _add_event=_add_event,
        ^^^^^^^^^^^^^^^^^^^^^^
    )
    ^
  File "C:\Users\dshan\portility\backend\venv\Lib\site-packages\sqlalchemy\orm\session.py", line 2249, in _execute_internal
    result: Result[Any] = compile_state_cls.orm_execute_statement(
                          ~~~~~~~~~~~~~~~~~~~~~~~~~~~~~~~~~~~~~~~^
        self,
        ^^^^^
    ...<4 lines>...
        conn,
        ^^^^^
    )
    ^
  File "C:\Users\dshan\portility\backend\venv\Lib\site-packages\sqlalchemy\orm\context.py", line 306, in orm_execute_statement
    result = conn.execute(
        statement, params or {}, execution_options=execution_options
    )
  File "C:\Users\dshan\portility\backend\venv\Lib\site-packages\sqlalchemy\engine\base.py", line 1419, in execute
    return meth(
        self,
        distilled_parameters,
        execution_options or NO_OPTIONS,
    )
  File "C:\Users\dshan\portility\backend\venv\Lib\site-packages\sqlalchemy\sql\elements.py", line 526, in _execute_on_connection
    return connection._execute_clauseelement(
           ~~~~~~~~~~~~~~~~~~~~~~~~~~~~~~~~~^
        self, distilled_params, execution_options
        ^^^^^^^^^^^^^^^^^^^^^^^^^^^^^^^^^^^^^^^^^
    )
    ^
  File "C:\Users\dshan\portility\backend\venv\Lib\site-packages\sqlalchemy\engine\base.py", line 1641, in _execute_clauseelement
    ret = self._execute_context(
        dialect,
    ...<8 lines>...
        cache_hit=cache_hit,
    )
  File "C:\Users\dshan\portility\backend\venv\Lib\site-packages\sqlalchemy\engine\base.py", line 1846, in _execute_context
    return self._exec_single_context(
           ~~~~~~~~~~~~~~~~~~~~~~~~~^
        dialect, context, statement, parameters
        ^^^^^^^^^^^^^^^^^^^^^^^^^^^^^^^^^^^^^^^
    )
    ^
  File "C:\Users\dshan\portility\backend\venv\Lib\site-packages\sqlalchemy\engine\base.py", line 1986, in _exec_single_context
    self._handle_dbapi_exception(
    ~~~~~~~~~~~~~~~~~~~~~~~~~~~~^
        e, str_statement, effective_parameters, cursor, context
        ^^^^^^^^^^^^^^^^^^^^^^^^^^^^^^^^^^^^^^^^^^^^^^^^^^^^^^^
    )
    ^
  File "C:\Users\dshan\portility\backend\venv\Lib\site-packages\sqlalchemy\engine\base.py", line 2355, in _handle_dbapi_exception
    raise sqlalchemy_exception.with_traceback(exc_info[2]) from e
  File "C:\Users\dshan\portility\backend\venv\Lib\site-packages\sqlalchemy\engine\base.py", line 1967, in _exec_single_context
    self.dialect.do_execute(
    ~~~~~~~~~~~~~~~~~~~~~~~^
        cursor, str_statement, effective_parameters, context
        ^^^^^^^^^^^^^^^^^^^^^^^^^^^^^^^^^^^^^^^^^^^^^^^^^^^^
    )
    ^
  File "C:\Users\dshan\portility\backend\venv\Lib\site-packages\sqlalchemy\engine\default.py", line 951, in do_execute
    cursor.execute(statement, parameters)
    ~~~~~~~~~~~~~~^^^^^^^^^^^^^^^^^^^^^^^
sqlalchemy.exc.OperationalError: (sqlite3.OperationalError) no such table: tasks
[SQL: SELECT tasks.id AS tasks_id, tasks.title AS tasks_title, tasks.description AS tasks_description, tasks.status AS tasks_status, tasks.due_date AS tasks_due_date, tasks.created_at AS tasks_created_at, tasks.updated_at AS tasks_updated_at 
FROM tasks ORDER BY tasks.created_at DESC]
(Background on this error at: https://sqlalche.me/e/20/e3q8)
2025-10-20 21:43:49,369 [INFO] GET /api/v1/tasks/ - from 127.0.0.1
2025-10-20 21:43:49,373 [ERROR] Unhandled exception: (sqlite3.OperationalError) no such table: tasks
[SQL: SELECT tasks.id AS tasks_id, tasks.title AS tasks_title, tasks.description AS tasks_description, tasks.status AS tasks_status, tasks.due_date AS tasks_due_date, tasks.created_at AS tasks_created_at, tasks.updated_at AS tasks_updated_at 
FROM tasks ORDER BY tasks.created_at DESC]
(Background on this error at: https://sqlalche.me/e/20/e3q8)
Traceback (most recent call last):
  File "C:\Users\dshan\portility\backend\venv\Lib\site-packages\sqlalchemy\engine\base.py", line 1967, in _exec_single_context
    self.dialect.do_execute(
    ~~~~~~~~~~~~~~~~~~~~~~~^
        cursor, str_statement, effective_parameters, context
        ^^^^^^^^^^^^^^^^^^^^^^^^^^^^^^^^^^^^^^^^^^^^^^^^^^^^
    )
    ^
  File "C:\Users\dshan\portility\backend\venv\Lib\site-packages\sqlalchemy\engine\default.py", line 951, in do_execute
    cursor.execute(statement, parameters)
    ~~~~~~~~~~~~~~^^^^^^^^^^^^^^^^^^^^^^^
sqlite3.OperationalError: no such table: tasks

The above exception was the direct cause of the following exception:

Traceback (most recent call last):
  File "C:\Users\dshan\portility\backend\venv\Lib\site-packages\flask\app.py", line 917, in full_dispatch_request
    rv = self.dispatch_request()
  File "C:\Users\dshan\portility\backend\venv\Lib\site-packages\flask\app.py", line 902, in dispatch_request
    return self.ensure_sync(self.view_functions[rule.endpoint])(**view_args)  # type: ignore[no-any-return]
           ~~~~~~~~~~~~~~~~~~~~~~~~~~~~~~~~~~~~~~~~~~~~~~~~~~~~^^^^^^^^^^^^^
  File "C:\Users\dshan\portility\backend\tasks\routes.py", line 12, in api_get_tasks
    all_tasks = get_tasks()
  File "C:\Users\dshan\portility\backend\tasks_store_sql.py", line 7, in get_tasks
    rows = Task.query.order_by(Task.created_at.desc()).all()
  File "C:\Users\dshan\portility\backend\venv\Lib\site-packages\sqlalchemy\orm\query.py", line 2704, in all
    return self._iter().all()  # type: ignore
           ~~~~~~~~~~^^
  File "C:\Users\dshan\portility\backend\venv\Lib\site-packages\sqlalchemy\orm\query.py", line 2857, in _iter
    result: Union[ScalarResult[_T], Result[_T]] = self.session.execute(
                                                  ~~~~~~~~~~~~~~~~~~~~^
        statement,
        ^^^^^^^^^^
        params,
        ^^^^^^^
        execution_options={"_sa_orm_load_options": self.load_options},
        ^^^^^^^^^^^^^^^^^^^^^^^^^^^^^^^^^^^^^^^^^^^^^^^^^^^^^^^^^^^^^^
    )
    ^
  File "C:\Users\dshan\portility\backend\venv\Lib\site-packages\sqlalchemy\orm\session.py", line 2351, in execute
    return self._execute_internal(
           ~~~~~~~~~~~~~~~~~~~~~~^
        statement,
        ^^^^^^^^^^
    ...<4 lines>...
        _add_event=_add_event,
        ^^^^^^^^^^^^^^^^^^^^^^
    )
    ^
  File "C:\Users\dshan\portility\backend\venv\Lib\site-packages\sqlalchemy\orm\session.py", line 2249, in _execute_internal
    result: Result[Any] = compile_state_cls.orm_execute_statement(
                          ~~~~~~~~~~~~~~~~~~~~~~~~~~~~~~~~~~~~~~~^
        self,
        ^^^^^
    ...<4 lines>...
        conn,
        ^^^^^
    )
    ^
  File "C:\Users\dshan\portility\backend\venv\Lib\site-packages\sqlalchemy\orm\context.py", line 306, in orm_execute_statement
    result = conn.execute(
        statement, params or {}, execution_options=execution_options
    )
  File "C:\Users\dshan\portility\backend\venv\Lib\site-packages\sqlalchemy\engine\base.py", line 1419, in execute
    return meth(
        self,
        distilled_parameters,
        execution_options or NO_OPTIONS,
    )
  File "C:\Users\dshan\portility\backend\venv\Lib\site-packages\sqlalchemy\sql\elements.py", line 526, in _execute_on_connection
    return connection._execute_clauseelement(
           ~~~~~~~~~~~~~~~~~~~~~~~~~~~~~~~~~^
        self, distilled_params, execution_options
        ^^^^^^^^^^^^^^^^^^^^^^^^^^^^^^^^^^^^^^^^^
    )
    ^
  File "C:\Users\dshan\portility\backend\venv\Lib\site-packages\sqlalchemy\engine\base.py", line 1641, in _execute_clauseelement
    ret = self._execute_context(
        dialect,
    ...<8 lines>...
        cache_hit=cache_hit,
    )
  File "C:\Users\dshan\portility\backend\venv\Lib\site-packages\sqlalchemy\engine\base.py", line 1846, in _execute_context
    return self._exec_single_context(
           ~~~~~~~~~~~~~~~~~~~~~~~~~^
        dialect, context, statement, parameters
        ^^^^^^^^^^^^^^^^^^^^^^^^^^^^^^^^^^^^^^^
    )
    ^
  File "C:\Users\dshan\portility\backend\venv\Lib\site-packages\sqlalchemy\engine\base.py", line 1986, in _exec_single_context
    self._handle_dbapi_exception(
    ~~~~~~~~~~~~~~~~~~~~~~~~~~~~^
        e, str_statement, effective_parameters, cursor, context
        ^^^^^^^^^^^^^^^^^^^^^^^^^^^^^^^^^^^^^^^^^^^^^^^^^^^^^^^
    )
    ^
  File "C:\Users\dshan\portility\backend\venv\Lib\site-packages\sqlalchemy\engine\base.py", line 2355, in _handle_dbapi_exception
    raise sqlalchemy_exception.with_traceback(exc_info[2]) from e
  File "C:\Users\dshan\portility\backend\venv\Lib\site-packages\sqlalchemy\engine\base.py", line 1967, in _exec_single_context
    self.dialect.do_execute(
    ~~~~~~~~~~~~~~~~~~~~~~~^
        cursor, str_statement, effective_parameters, context
        ^^^^^^^^^^^^^^^^^^^^^^^^^^^^^^^^^^^^^^^^^^^^^^^^^^^^
    )
    ^
  File "C:\Users\dshan\portility\backend\venv\Lib\site-packages\sqlalchemy\engine\default.py", line 951, in do_execute
    cursor.execute(statement, parameters)
    ~~~~~~~~~~~~~~^^^^^^^^^^^^^^^^^^^^^^^
sqlalchemy.exc.OperationalError: (sqlite3.OperationalError) no such table: tasks
[SQL: SELECT tasks.id AS tasks_id, tasks.title AS tasks_title, tasks.description AS tasks_description, tasks.status AS tasks_status, tasks.due_date AS tasks_due_date, tasks.created_at AS tasks_created_at, tasks.updated_at AS tasks_updated_at 
FROM tasks ORDER BY tasks.created_at DESC]
(Background on this error at: https://sqlalche.me/e/20/e3q8)
2025-10-21 17:44:49,877 [INFO] Registered tasks blueprint at /api/v1/tasks
2025-10-21 17:48:50,921 [WARNING] Could not import/register tasks blueprint: cannot import name 'bp' from partially initialized module 'backend.tasks.routes' (most likely due to a circular import) (C:\Users\dshan\portility\backend\tasks\routes.py)
2025-10-21 17:48:50,931 [INFO] Registered tasks blueprint at /api/v1/tasks
2025-10-21 17:48:52,995 [WARNING] Could not import/register tasks blueprint: cannot import name 'bp' from partially initialized module 'backend.tasks.routes' (most likely due to a circular import) (C:\Users\dshan\portility\backend\tasks\routes.py)
2025-10-21 17:48:53,005 [INFO] Registered tasks blueprint at /api/v1/tasks
2025-10-21 17:49:25,459 [INFO] GET / - from 127.0.0.1
2025-10-21 17:49:28,382 [INFO] GET /favicon.ico - from 127.0.0.1
2025-10-21 18:16:57,335 [INFO] Registered tasks blueprint at /api/v1/tasks
2025-10-21 18:17:09,896 [WARNING] Could not import/register tasks blueprint: cannot import name 'bp' from partially initialized module 'backend.tasks.routes' (most likely due to a circular import) (C:\Users\dshan\portility\backend\tasks\routes.py)
2025-10-21 18:17:09,909 [INFO] Registered tasks blueprint at /api/v1/tasks
2025-10-21 18:17:11,466 [WARNING] Could not import/register tasks blueprint: cannot import name 'bp' from partially initialized module 'backend.tasks.routes' (most likely due to a circular import) (C:\Users\dshan\portility\backend\tasks\routes.py)
2025-10-21 18:17:11,476 [INFO] Registered tasks blueprint at /api/v1/tasks
2025-10-21 18:18:03,608 [WARNING] Could not import/register tasks blueprint: cannot import name 'bp' from partially initialized module 'backend.tasks.routes' (most likely due to a circular import) (C:\Users\dshan\portility\backend\tasks\routes.py)
2025-10-21 18:18:03,619 [INFO] Registered tasks blueprint at /api/v1/tasks
2025-10-21 18:18:05,000 [WARNING] Could not import/register tasks blueprint: cannot import name 'bp' from partially initialized module 'backend.tasks.routes' (most likely due to a circular import) (C:\Users\dshan\portility\backend\tasks\routes.py)
2025-10-21 18:18:05,010 [INFO] Registered tasks blueprint at /api/v1/tasks
2025-10-21 18:19:08,272 [WARNING] Could not import/register tasks blueprint: cannot import name 'bp' from partially initialized module 'backend.tasks.routes' (most likely due to a circular import) (C:\Users\dshan\portility\backend\tasks\routes.py)
2025-10-21 18:19:08,287 [INFO] Registered tasks blueprint at /api/v1/tasks
2025-10-21 18:19:32,405 [INFO] GET /api/ping - from 127.0.0.1
2025-10-21 18:20:38,737 [INFO] GET /api/ping - from 127.0.0.1
2025-10-21 18:20:45,989 [INFO] GET /api/v1/tasks/ - from 127.0.0.1
2025-10-21 18:20:46,185 [ERROR] Unhandled exception: (sqlite3.OperationalError) no such table: tasks
[SQL: SELECT tasks.id AS tasks_id, tasks.title AS tasks_title, tasks.description AS tasks_description, tasks.status AS tasks_status, tasks.due_date AS tasks_due_date, tasks.created_at AS tasks_created_at, tasks.updated_at AS tasks_updated_at 
FROM tasks ORDER BY tasks.created_at DESC]
(Background on this error at: https://sqlalche.me/e/20/e3q8)
Traceback (most recent call last):
  File "C:\Users\dshan\portility\backend\venv\Lib\site-packages\sqlalchemy\engine\base.py", line 1967, in _exec_single_context
    self.dialect.do_execute(
    ~~~~~~~~~~~~~~~~~~~~~~~^
        cursor, str_statement, effective_parameters, context
        ^^^^^^^^^^^^^^^^^^^^^^^^^^^^^^^^^^^^^^^^^^^^^^^^^^^^
    )
    ^
  File "C:\Users\dshan\portility\backend\venv\Lib\site-packages\sqlalchemy\engine\default.py", line 951, in do_execute
    cursor.execute(statement, parameters)
    ~~~~~~~~~~~~~~^^^^^^^^^^^^^^^^^^^^^^^
sqlite3.OperationalError: no such table: tasks

The above exception was the direct cause of the following exception:

Traceback (most recent call last):
  File "C:\Users\dshan\portility\backend\venv\Lib\site-packages\flask\app.py", line 917, in full_dispatch_request
    rv = self.dispatch_request()
  File "C:\Users\dshan\portility\backend\venv\Lib\site-packages\flask\app.py", line 902, in dispatch_request
    return self.ensure_sync(self.view_functions[rule.endpoint])(**view_args)  # type: ignore[no-any-return]
           ~~~~~~~~~~~~~~~~~~~~~~~~~~~~~~~~~~~~~~~~~~~~~~~~~~~~^^^^^^^^^^^^^
  File "C:\Users\dshan\portility\backend\tasks\routes.py", line 12, in api_get_tasks
    all_tasks = get_tasks()
  File "C:\Users\dshan\portility\backend\tasks_store_sql.py", line 7, in get_tasks
    rows = Task.query.order_by(Task.created_at.desc()).all()
  File "C:\Users\dshan\portility\backend\venv\Lib\site-packages\sqlalchemy\orm\query.py", line 2704, in all
    return self._iter().all()  # type: ignore
           ~~~~~~~~~~^^
  File "C:\Users\dshan\portility\backend\venv\Lib\site-packages\sqlalchemy\orm\query.py", line 2857, in _iter
    result: Union[ScalarResult[_T], Result[_T]] = self.session.execute(
                                                  ~~~~~~~~~~~~~~~~~~~~^
        statement,
        ^^^^^^^^^^
        params,
        ^^^^^^^
        execution_options={"_sa_orm_load_options": self.load_options},
        ^^^^^^^^^^^^^^^^^^^^^^^^^^^^^^^^^^^^^^^^^^^^^^^^^^^^^^^^^^^^^^
    )
    ^
  File "C:\Users\dshan\portility\backend\venv\Lib\site-packages\sqlalchemy\orm\session.py", line 2351, in execute
    return self._execute_internal(
           ~~~~~~~~~~~~~~~~~~~~~~^
        statement,
        ^^^^^^^^^^
    ...<4 lines>...
        _add_event=_add_event,
        ^^^^^^^^^^^^^^^^^^^^^^
    )
    ^
  File "C:\Users\dshan\portility\backend\venv\Lib\site-packages\sqlalchemy\orm\session.py", line 2249, in _execute_internal
    result: Result[Any] = compile_state_cls.orm_execute_statement(
                          ~~~~~~~~~~~~~~~~~~~~~~~~~~~~~~~~~~~~~~~^
        self,
        ^^^^^
    ...<4 lines>...
        conn,
        ^^^^^
    )
    ^
  File "C:\Users\dshan\portility\backend\venv\Lib\site-packages\sqlalchemy\orm\context.py", line 306, in orm_execute_statement
    result = conn.execute(
        statement, params or {}, execution_options=execution_options
    )
  File "C:\Users\dshan\portility\backend\venv\Lib\site-packages\sqlalchemy\engine\base.py", line 1419, in execute
    return meth(
        self,
        distilled_parameters,
        execution_options or NO_OPTIONS,
    )
  File "C:\Users\dshan\portility\backend\venv\Lib\site-packages\sqlalchemy\sql\elements.py", line 526, in _execute_on_connection
    return connection._execute_clauseelement(
           ~~~~~~~~~~~~~~~~~~~~~~~~~~~~~~~~~^
        self, distilled_params, execution_options
        ^^^^^^^^^^^^^^^^^^^^^^^^^^^^^^^^^^^^^^^^^
    )
    ^
  File "C:\Users\dshan\portility\backend\venv\Lib\site-packages\sqlalchemy\engine\base.py", line 1641, in _execute_clauseelement
    ret = self._execute_context(
        dialect,
    ...<8 lines>...
        cache_hit=cache_hit,
    )
  File "C:\Users\dshan\portility\backend\venv\Lib\site-packages\sqlalchemy\engine\base.py", line 1846, in _execute_context
    return self._exec_single_context(
           ~~~~~~~~~~~~~~~~~~~~~~~~~^
        dialect, context, statement, parameters
        ^^^^^^^^^^^^^^^^^^^^^^^^^^^^^^^^^^^^^^^
    )
    ^
  File "C:\Users\dshan\portility\backend\venv\Lib\site-packages\sqlalchemy\engine\base.py", line 1986, in _exec_single_context
    self._handle_dbapi_exception(
    ~~~~~~~~~~~~~~~~~~~~~~~~~~~~^
        e, str_statement, effective_parameters, cursor, context
        ^^^^^^^^^^^^^^^^^^^^^^^^^^^^^^^^^^^^^^^^^^^^^^^^^^^^^^^
    )
    ^
  File "C:\Users\dshan\portility\backend\venv\Lib\site-packages\sqlalchemy\engine\base.py", line 2355, in _handle_dbapi_exception
    raise sqlalchemy_exception.with_traceback(exc_info[2]) from e
  File "C:\Users\dshan\portility\backend\venv\Lib\site-packages\sqlalchemy\engine\base.py", line 1967, in _exec_single_context
    self.dialect.do_execute(
    ~~~~~~~~~~~~~~~~~~~~~~~^
        cursor, str_statement, effective_parameters, context
        ^^^^^^^^^^^^^^^^^^^^^^^^^^^^^^^^^^^^^^^^^^^^^^^^^^^^
    )
    ^
  File "C:\Users\dshan\portility\backend\venv\Lib\site-packages\sqlalchemy\engine\default.py", line 951, in do_execute
    cursor.execute(statement, parameters)
    ~~~~~~~~~~~~~~^^^^^^^^^^^^^^^^^^^^^^^
sqlalchemy.exc.OperationalError: (sqlite3.OperationalError) no such table: tasks
[SQL: SELECT tasks.id AS tasks_id, tasks.title AS tasks_title, tasks.description AS tasks_description, tasks.status AS tasks_status, tasks.due_date AS tasks_due_date, tasks.created_at AS tasks_created_at, tasks.updated_at AS tasks_updated_at 
FROM tasks ORDER BY tasks.created_at DESC]
(Background on this error at: https://sqlalche.me/e/20/e3q8)
2025-10-21 18:20:46,673 [INFO] GET /api/v1/tasks/ - from 127.0.0.1
2025-10-21 18:20:46,677 [ERROR] Unhandled exception: (sqlite3.OperationalError) no such table: tasks
[SQL: SELECT tasks.id AS tasks_id, tasks.title AS tasks_title, tasks.description AS tasks_description, tasks.status AS tasks_status, tasks.due_date AS tasks_due_date, tasks.created_at AS tasks_created_at, tasks.updated_at AS tasks_updated_at 
FROM tasks ORDER BY tasks.created_at DESC]
(Background on this error at: https://sqlalche.me/e/20/e3q8)
Traceback (most recent call last):
  File "C:\Users\dshan\portility\backend\venv\Lib\site-packages\sqlalchemy\engine\base.py", line 1967, in _exec_single_context
    self.dialect.do_execute(
    ~~~~~~~~~~~~~~~~~~~~~~~^
        cursor, str_statement, effective_parameters, context
        ^^^^^^^^^^^^^^^^^^^^^^^^^^^^^^^^^^^^^^^^^^^^^^^^^^^^
    )
    ^
  File "C:\Users\dshan\portility\backend\venv\Lib\site-packages\sqlalchemy\engine\default.py", line 951, in do_execute
    cursor.execute(statement, parameters)
    ~~~~~~~~~~~~~~^^^^^^^^^^^^^^^^^^^^^^^
sqlite3.OperationalError: no such table: tasks

The above exception was the direct cause of the following exception:

Traceback (most recent call last):
  File "C:\Users\dshan\portility\backend\venv\Lib\site-packages\flask\app.py", line 917, in full_dispatch_request
    rv = self.dispatch_request()
  File "C:\Users\dshan\portility\backend\venv\Lib\site-packages\flask\app.py", line 902, in dispatch_request
    return self.ensure_sync(self.view_functions[rule.endpoint])(**view_args)  # type: ignore[no-any-return]
           ~~~~~~~~~~~~~~~~~~~~~~~~~~~~~~~~~~~~~~~~~~~~~~~~~~~~^^^^^^^^^^^^^
  File "C:\Users\dshan\portility\backend\tasks\routes.py", line 12, in api_get_tasks
    all_tasks = get_tasks()
  File "C:\Users\dshan\portility\backend\tasks_store_sql.py", line 7, in get_tasks
    rows = Task.query.order_by(Task.created_at.desc()).all()
  File "C:\Users\dshan\portility\backend\venv\Lib\site-packages\sqlalchemy\orm\query.py", line 2704, in all
    return self._iter().all()  # type: ignore
           ~~~~~~~~~~^^
  File "C:\Users\dshan\portility\backend\venv\Lib\site-packages\sqlalchemy\orm\query.py", line 2857, in _iter
    result: Union[ScalarResult[_T], Result[_T]] = self.session.execute(
                                                  ~~~~~~~~~~~~~~~~~~~~^
        statement,
        ^^^^^^^^^^
        params,
        ^^^^^^^
        execution_options={"_sa_orm_load_options": self.load_options},
        ^^^^^^^^^^^^^^^^^^^^^^^^^^^^^^^^^^^^^^^^^^^^^^^^^^^^^^^^^^^^^^
    )
    ^
  File "C:\Users\dshan\portility\backend\venv\Lib\site-packages\sqlalchemy\orm\session.py", line 2351, in execute
    return self._execute_internal(
           ~~~~~~~~~~~~~~~~~~~~~~^
        statement,
        ^^^^^^^^^^
    ...<4 lines>...
        _add_event=_add_event,
        ^^^^^^^^^^^^^^^^^^^^^^
    )
    ^
  File "C:\Users\dshan\portility\backend\venv\Lib\site-packages\sqlalchemy\orm\session.py", line 2249, in _execute_internal
    result: Result[Any] = compile_state_cls.orm_execute_statement(
                          ~~~~~~~~~~~~~~~~~~~~~~~~~~~~~~~~~~~~~~~^
        self,
        ^^^^^
    ...<4 lines>...
        conn,
        ^^^^^
    )
    ^
  File "C:\Users\dshan\portility\backend\venv\Lib\site-packages\sqlalchemy\orm\context.py", line 306, in orm_execute_statement
    result = conn.execute(
        statement, params or {}, execution_options=execution_options
    )
  File "C:\Users\dshan\portility\backend\venv\Lib\site-packages\sqlalchemy\engine\base.py", line 1419, in execute
    return meth(
        self,
        distilled_parameters,
        execution_options or NO_OPTIONS,
    )
  File "C:\Users\dshan\portility\backend\venv\Lib\site-packages\sqlalchemy\sql\elements.py", line 526, in _execute_on_connection
    return connection._execute_clauseelement(
           ~~~~~~~~~~~~~~~~~~~~~~~~~~~~~~~~~^
        self, distilled_params, execution_options
        ^^^^^^^^^^^^^^^^^^^^^^^^^^^^^^^^^^^^^^^^^
    )
    ^
  File "C:\Users\dshan\portility\backend\venv\Lib\site-packages\sqlalchemy\engine\base.py", line 1641, in _execute_clauseelement
    ret = self._execute_context(
        dialect,
    ...<8 lines>...
        cache_hit=cache_hit,
    )
  File "C:\Users\dshan\portility\backend\venv\Lib\site-packages\sqlalchemy\engine\base.py", line 1846, in _execute_context
    return self._exec_single_context(
           ~~~~~~~~~~~~~~~~~~~~~~~~~^
        dialect, context, statement, parameters
        ^^^^^^^^^^^^^^^^^^^^^^^^^^^^^^^^^^^^^^^
    )
    ^
  File "C:\Users\dshan\portility\backend\venv\Lib\site-packages\sqlalchemy\engine\base.py", line 1986, in _exec_single_context
    self._handle_dbapi_exception(
    ~~~~~~~~~~~~~~~~~~~~~~~~~~~~^
        e, str_statement, effective_parameters, cursor, context
        ^^^^^^^^^^^^^^^^^^^^^^^^^^^^^^^^^^^^^^^^^^^^^^^^^^^^^^^
    )
    ^
  File "C:\Users\dshan\portility\backend\venv\Lib\site-packages\sqlalchemy\engine\base.py", line 2355, in _handle_dbapi_exception
    raise sqlalchemy_exception.with_traceback(exc_info[2]) from e
  File "C:\Users\dshan\portility\backend\venv\Lib\site-packages\sqlalchemy\engine\base.py", line 1967, in _exec_single_context
    self.dialect.do_execute(
    ~~~~~~~~~~~~~~~~~~~~~~~^
        cursor, str_statement, effective_parameters, context
        ^^^^^^^^^^^^^^^^^^^^^^^^^^^^^^^^^^^^^^^^^^^^^^^^^^^^
    )
    ^
  File "C:\Users\dshan\portility\backend\venv\Lib\site-packages\sqlalchemy\engine\default.py", line 951, in do_execute
    cursor.execute(statement, parameters)
    ~~~~~~~~~~~~~~^^^^^^^^^^^^^^^^^^^^^^^
sqlalchemy.exc.OperationalError: (sqlite3.OperationalError) no such table: tasks
[SQL: SELECT tasks.id AS tasks_id, tasks.title AS tasks_title, tasks.description AS tasks_description, tasks.status AS tasks_status, tasks.due_date AS tasks_due_date, tasks.created_at AS tasks_created_at, tasks.updated_at AS tasks_updated_at 
FROM tasks ORDER BY tasks.created_at DESC]
(Background on this error at: https://sqlalche.me/e/20/e3q8)
2025-10-21 18:24:27,998 [INFO] GET /api/v1/tasks/ - from 127.0.0.1
2025-10-21 18:24:28,001 [ERROR] Unhandled exception: (sqlite3.OperationalError) no such table: tasks
[SQL: SELECT tasks.id AS tasks_id, tasks.title AS tasks_title, tasks.description AS tasks_description, tasks.status AS tasks_status, tasks.due_date AS tasks_due_date, tasks.created_at AS tasks_created_at, tasks.updated_at AS tasks_updated_at 
FROM tasks ORDER BY tasks.created_at DESC]
(Background on this error at: https://sqlalche.me/e/20/e3q8)
Traceback (most recent call last):
  File "C:\Users\dshan\portility\backend\venv\Lib\site-packages\sqlalchemy\engine\base.py", line 1967, in _exec_single_context
    self.dialect.do_execute(
    ~~~~~~~~~~~~~~~~~~~~~~~^
        cursor, str_statement, effective_parameters, context
        ^^^^^^^^^^^^^^^^^^^^^^^^^^^^^^^^^^^^^^^^^^^^^^^^^^^^
    )
    ^
  File "C:\Users\dshan\portility\backend\venv\Lib\site-packages\sqlalchemy\engine\default.py", line 951, in do_execute
    cursor.execute(statement, parameters)
    ~~~~~~~~~~~~~~^^^^^^^^^^^^^^^^^^^^^^^
sqlite3.OperationalError: no such table: tasks

The above exception was the direct cause of the following exception:

Traceback (most recent call last):
  File "C:\Users\dshan\portility\backend\venv\Lib\site-packages\flask\app.py", line 917, in full_dispatch_request
    rv = self.dispatch_request()
  File "C:\Users\dshan\portility\backend\venv\Lib\site-packages\flask\app.py", line 902, in dispatch_request
    return self.ensure_sync(self.view_functions[rule.endpoint])(**view_args)  # type: ignore[no-any-return]
           ~~~~~~~~~~~~~~~~~~~~~~~~~~~~~~~~~~~~~~~~~~~~~~~~~~~~^^^^^^^^^^^^^
  File "C:\Users\dshan\portility\backend\tasks\routes.py", line 12, in api_get_tasks
    all_tasks = get_tasks()
  File "C:\Users\dshan\portility\backend\tasks_store_sql.py", line 7, in get_tasks
    rows = Task.query.order_by(Task.created_at.desc()).all()
  File "C:\Users\dshan\portility\backend\venv\Lib\site-packages\sqlalchemy\orm\query.py", line 2704, in all
    return self._iter().all()  # type: ignore
           ~~~~~~~~~~^^
  File "C:\Users\dshan\portility\backend\venv\Lib\site-packages\sqlalchemy\orm\query.py", line 2857, in _iter
    result: Union[ScalarResult[_T], Result[_T]] = self.session.execute(
                                                  ~~~~~~~~~~~~~~~~~~~~^
        statement,
        ^^^^^^^^^^
        params,
        ^^^^^^^
        execution_options={"_sa_orm_load_options": self.load_options},
        ^^^^^^^^^^^^^^^^^^^^^^^^^^^^^^^^^^^^^^^^^^^^^^^^^^^^^^^^^^^^^^
    )
    ^
  File "C:\Users\dshan\portility\backend\venv\Lib\site-packages\sqlalchemy\orm\session.py", line 2351, in execute
    return self._execute_internal(
           ~~~~~~~~~~~~~~~~~~~~~~^
        statement,
        ^^^^^^^^^^
    ...<4 lines>...
        _add_event=_add_event,
        ^^^^^^^^^^^^^^^^^^^^^^
    )
    ^
  File "C:\Users\dshan\portility\backend\venv\Lib\site-packages\sqlalchemy\orm\session.py", line 2249, in _execute_internal
    result: Result[Any] = compile_state_cls.orm_execute_statement(
                          ~~~~~~~~~~~~~~~~~~~~~~~~~~~~~~~~~~~~~~~^
        self,
        ^^^^^
    ...<4 lines>...
        conn,
        ^^^^^
    )
    ^
  File "C:\Users\dshan\portility\backend\venv\Lib\site-packages\sqlalchemy\orm\context.py", line 306, in orm_execute_statement
    result = conn.execute(
        statement, params or {}, execution_options=execution_options
    )
  File "C:\Users\dshan\portility\backend\venv\Lib\site-packages\sqlalchemy\engine\base.py", line 1419, in execute
    return meth(
        self,
        distilled_parameters,
        execution_options or NO_OPTIONS,
    )
  File "C:\Users\dshan\portility\backend\venv\Lib\site-packages\sqlalchemy\sql\elements.py", line 526, in _execute_on_connection
    return connection._execute_clauseelement(
           ~~~~~~~~~~~~~~~~~~~~~~~~~~~~~~~~~^
        self, distilled_params, execution_options
        ^^^^^^^^^^^^^^^^^^^^^^^^^^^^^^^^^^^^^^^^^
    )
    ^
  File "C:\Users\dshan\portility\backend\venv\Lib\site-packages\sqlalchemy\engine\base.py", line 1641, in _execute_clauseelement
    ret = self._execute_context(
        dialect,
    ...<8 lines>...
        cache_hit=cache_hit,
    )
  File "C:\Users\dshan\portility\backend\venv\Lib\site-packages\sqlalchemy\engine\base.py", line 1846, in _execute_context
    return self._exec_single_context(
           ~~~~~~~~~~~~~~~~~~~~~~~~~^
        dialect, context, statement, parameters
        ^^^^^^^^^^^^^^^^^^^^^^^^^^^^^^^^^^^^^^^
    )
    ^
  File "C:\Users\dshan\portility\backend\venv\Lib\site-packages\sqlalchemy\engine\base.py", line 1986, in _exec_single_context
    self._handle_dbapi_exception(
    ~~~~~~~~~~~~~~~~~~~~~~~~~~~~^
        e, str_statement, effective_parameters, cursor, context
        ^^^^^^^^^^^^^^^^^^^^^^^^^^^^^^^^^^^^^^^^^^^^^^^^^^^^^^^
    )
    ^
  File "C:\Users\dshan\portility\backend\venv\Lib\site-packages\sqlalchemy\engine\base.py", line 2355, in _handle_dbapi_exception
    raise sqlalchemy_exception.with_traceback(exc_info[2]) from e
  File "C:\Users\dshan\portility\backend\venv\Lib\site-packages\sqlalchemy\engine\base.py", line 1967, in _exec_single_context
    self.dialect.do_execute(
    ~~~~~~~~~~~~~~~~~~~~~~~^
        cursor, str_statement, effective_parameters, context
        ^^^^^^^^^^^^^^^^^^^^^^^^^^^^^^^^^^^^^^^^^^^^^^^^^^^^
    )
    ^
  File "C:\Users\dshan\portility\backend\venv\Lib\site-packages\sqlalchemy\engine\default.py", line 951, in do_execute
    cursor.execute(statement, parameters)
    ~~~~~~~~~~~~~~^^^^^^^^^^^^^^^^^^^^^^^
sqlalchemy.exc.OperationalError: (sqlite3.OperationalError) no such table: tasks
[SQL: SELECT tasks.id AS tasks_id, tasks.title AS tasks_title, tasks.description AS tasks_description, tasks.status AS tasks_status, tasks.due_date AS tasks_due_date, tasks.created_at AS tasks_created_at, tasks.updated_at AS tasks_updated_at 
FROM tasks ORDER BY tasks.created_at DESC]
(Background on this error at: https://sqlalche.me/e/20/e3q8)
2025-10-21 19:36:40,572 [WARNING] Could not import/register tasks blueprint: cannot import name 'bp' from partially initialized module 'backend.tasks.routes' (most likely due to a circular import) (C:\Users\dshan\portility\backend\tasks\routes.py)
2025-10-21 19:36:40,589 [INFO] Registered tasks blueprint at /api/v1/tasks
2025-10-21 19:37:11,184 [INFO] Registered tasks blueprint at /api/v1/tasks
2025-10-21 19:40:02,286 [INFO] Registered tasks blueprint at /api/v1/tasks
2025-10-21 19:40:07,006 [INFO] Registered tasks blueprint at /api/v1/tasks
2025-10-21 19:40:11,012 [INFO] Registered tasks blueprint at /api/v1/tasks
2025-10-21 19:40:33,126 [INFO] GET /api/v1/tasks/ - from 127.0.0.1
2025-10-21 19:40:33,144 [ERROR] Unhandled exception: (sqlite3.OperationalError) no such table: tasks
[SQL: SELECT tasks.id AS tasks_id, tasks.title AS tasks_title, tasks.description AS tasks_description, tasks.status AS tasks_status, tasks.due_date AS tasks_due_date, tasks.created_at AS tasks_created_at, tasks.updated_at AS tasks_updated_at 
FROM tasks ORDER BY tasks.created_at DESC]
(Background on this error at: https://sqlalche.me/e/20/e3q8)
Traceback (most recent call last):
  File "C:\Users\dshan\portility\backend\venv\Lib\site-packages\sqlalchemy\engine\base.py", line 1967, in _exec_single_context
    self.dialect.do_execute(
    ~~~~~~~~~~~~~~~~~~~~~~~^
        cursor, str_statement, effective_parameters, context
        ^^^^^^^^^^^^^^^^^^^^^^^^^^^^^^^^^^^^^^^^^^^^^^^^^^^^
    )
    ^
  File "C:\Users\dshan\portility\backend\venv\Lib\site-packages\sqlalchemy\engine\default.py", line 951, in do_execute
    cursor.execute(statement, parameters)
    ~~~~~~~~~~~~~~^^^^^^^^^^^^^^^^^^^^^^^
sqlite3.OperationalError: no such table: tasks

The above exception was the direct cause of the following exception:

Traceback (most recent call last):
  File "C:\Users\dshan\portility\backend\venv\Lib\site-packages\flask\app.py", line 917, in full_dispatch_request
    rv = self.dispatch_request()
  File "C:\Users\dshan\portility\backend\venv\Lib\site-packages\flask\app.py", line 902, in dispatch_request
    return self.ensure_sync(self.view_functions[rule.endpoint])(**view_args)  # type: ignore[no-any-return]
           ~~~~~~~~~~~~~~~~~~~~~~~~~~~~~~~~~~~~~~~~~~~~~~~~~~~~^^^^^^^^^^^^^
  File "C:\Users\dshan\portility\backend\tasks\routes.py", line 12, in api_get_tasks
    all_tasks = get_tasks()
  File "C:\Users\dshan\portility\backend\tasks_store_sql.py", line 7, in get_tasks
    rows = Task.query.order_by(Task.created_at.desc()).all()
  File "C:\Users\dshan\portility\backend\venv\Lib\site-packages\sqlalchemy\orm\query.py", line 2704, in all
    return self._iter().all()  # type: ignore
           ~~~~~~~~~~^^
  File "C:\Users\dshan\portility\backend\venv\Lib\site-packages\sqlalchemy\orm\query.py", line 2857, in _iter
    result: Union[ScalarResult[_T], Result[_T]] = self.session.execute(
                                                  ~~~~~~~~~~~~~~~~~~~~^
        statement,
        ^^^^^^^^^^
        params,
        ^^^^^^^
        execution_options={"_sa_orm_load_options": self.load_options},
        ^^^^^^^^^^^^^^^^^^^^^^^^^^^^^^^^^^^^^^^^^^^^^^^^^^^^^^^^^^^^^^
    )
    ^
  File "C:\Users\dshan\portility\backend\venv\Lib\site-packages\sqlalchemy\orm\session.py", line 2351, in execute
    return self._execute_internal(
           ~~~~~~~~~~~~~~~~~~~~~~^
        statement,
        ^^^^^^^^^^
    ...<4 lines>...
        _add_event=_add_event,
        ^^^^^^^^^^^^^^^^^^^^^^
    )
    ^
  File "C:\Users\dshan\portility\backend\venv\Lib\site-packages\sqlalchemy\orm\session.py", line 2249, in _execute_internal
    result: Result[Any] = compile_state_cls.orm_execute_statement(
                          ~~~~~~~~~~~~~~~~~~~~~~~~~~~~~~~~~~~~~~~^
        self,
        ^^^^^
    ...<4 lines>...
        conn,
        ^^^^^
    )
    ^
  File "C:\Users\dshan\portility\backend\venv\Lib\site-packages\sqlalchemy\orm\context.py", line 306, in orm_execute_statement
    result = conn.execute(
        statement, params or {}, execution_options=execution_options
    )
  File "C:\Users\dshan\portility\backend\venv\Lib\site-packages\sqlalchemy\engine\base.py", line 1419, in execute
    return meth(
        self,
        distilled_parameters,
        execution_options or NO_OPTIONS,
    )
  File "C:\Users\dshan\portility\backend\venv\Lib\site-packages\sqlalchemy\sql\elements.py", line 526, in _execute_on_connection
    return connection._execute_clauseelement(
           ~~~~~~~~~~~~~~~~~~~~~~~~~~~~~~~~~^
        self, distilled_params, execution_options
        ^^^^^^^^^^^^^^^^^^^^^^^^^^^^^^^^^^^^^^^^^
    )
    ^
  File "C:\Users\dshan\portility\backend\venv\Lib\site-packages\sqlalchemy\engine\base.py", line 1641, in _execute_clauseelement
    ret = self._execute_context(
        dialect,
    ...<8 lines>...
        cache_hit=cache_hit,
    )
  File "C:\Users\dshan\portility\backend\venv\Lib\site-packages\sqlalchemy\engine\base.py", line 1846, in _execute_context
    return self._exec_single_context(
           ~~~~~~~~~~~~~~~~~~~~~~~~~^
        dialect, context, statement, parameters
        ^^^^^^^^^^^^^^^^^^^^^^^^^^^^^^^^^^^^^^^
    )
    ^
  File "C:\Users\dshan\portility\backend\venv\Lib\site-packages\sqlalchemy\engine\base.py", line 1986, in _exec_single_context
    self._handle_dbapi_exception(
    ~~~~~~~~~~~~~~~~~~~~~~~~~~~~^
        e, str_statement, effective_parameters, cursor, context
        ^^^^^^^^^^^^^^^^^^^^^^^^^^^^^^^^^^^^^^^^^^^^^^^^^^^^^^^
    )
    ^
  File "C:\Users\dshan\portility\backend\venv\Lib\site-packages\sqlalchemy\engine\base.py", line 2355, in _handle_dbapi_exception
    raise sqlalchemy_exception.with_traceback(exc_info[2]) from e
  File "C:\Users\dshan\portility\backend\venv\Lib\site-packages\sqlalchemy\engine\base.py", line 1967, in _exec_single_context
    self.dialect.do_execute(
    ~~~~~~~~~~~~~~~~~~~~~~~^
        cursor, str_statement, effective_parameters, context
        ^^^^^^^^^^^^^^^^^^^^^^^^^^^^^^^^^^^^^^^^^^^^^^^^^^^^
    )
    ^
  File "C:\Users\dshan\portility\backend\venv\Lib\site-packages\sqlalchemy\engine\default.py", line 951, in do_execute
    cursor.execute(statement, parameters)
    ~~~~~~~~~~~~~~^^^^^^^^^^^^^^^^^^^^^^^
sqlalchemy.exc.OperationalError: (sqlite3.OperationalError) no such table: tasks
[SQL: SELECT tasks.id AS tasks_id, tasks.title AS tasks_title, tasks.description AS tasks_description, tasks.status AS tasks_status, tasks.due_date AS tasks_due_date, tasks.created_at AS tasks_created_at, tasks.updated_at AS tasks_updated_at 
FROM tasks ORDER BY tasks.created_at DESC]
(Background on this error at: https://sqlalche.me/e/20/e3q8)
2025-10-21 19:40:33,397 [INFO] GET /api/v1/tasks/ - from 127.0.0.1
2025-10-21 19:40:33,401 [ERROR] Unhandled exception: (sqlite3.OperationalError) no such table: tasks
[SQL: SELECT tasks.id AS tasks_id, tasks.title AS tasks_title, tasks.description AS tasks_description, tasks.status AS tasks_status, tasks.due_date AS tasks_due_date, tasks.created_at AS tasks_created_at, tasks.updated_at AS tasks_updated_at 
FROM tasks ORDER BY tasks.created_at DESC]
(Background on this error at: https://sqlalche.me/e/20/e3q8)
Traceback (most recent call last):
  File "C:\Users\dshan\portility\backend\venv\Lib\site-packages\sqlalchemy\engine\base.py", line 1967, in _exec_single_context
    self.dialect.do_execute(
    ~~~~~~~~~~~~~~~~~~~~~~~^
        cursor, str_statement, effective_parameters, context
        ^^^^^^^^^^^^^^^^^^^^^^^^^^^^^^^^^^^^^^^^^^^^^^^^^^^^
    )
    ^
  File "C:\Users\dshan\portility\backend\venv\Lib\site-packages\sqlalchemy\engine\default.py", line 951, in do_execute
    cursor.execute(statement, parameters)
    ~~~~~~~~~~~~~~^^^^^^^^^^^^^^^^^^^^^^^
sqlite3.OperationalError: no such table: tasks

The above exception was the direct cause of the following exception:

Traceback (most recent call last):
  File "C:\Users\dshan\portility\backend\venv\Lib\site-packages\flask\app.py", line 917, in full_dispatch_request
    rv = self.dispatch_request()
  File "C:\Users\dshan\portility\backend\venv\Lib\site-packages\flask\app.py", line 902, in dispatch_request
    return self.ensure_sync(self.view_functions[rule.endpoint])(**view_args)  # type: ignore[no-any-return]
           ~~~~~~~~~~~~~~~~~~~~~~~~~~~~~~~~~~~~~~~~~~~~~~~~~~~~^^^^^^^^^^^^^
  File "C:\Users\dshan\portility\backend\tasks\routes.py", line 12, in api_get_tasks
    all_tasks = get_tasks()
  File "C:\Users\dshan\portility\backend\tasks_store_sql.py", line 7, in get_tasks
    rows = Task.query.order_by(Task.created_at.desc()).all()
  File "C:\Users\dshan\portility\backend\venv\Lib\site-packages\sqlalchemy\orm\query.py", line 2704, in all
    return self._iter().all()  # type: ignore
           ~~~~~~~~~~^^
  File "C:\Users\dshan\portility\backend\venv\Lib\site-packages\sqlalchemy\orm\query.py", line 2857, in _iter
    result: Union[ScalarResult[_T], Result[_T]] = self.session.execute(
                                                  ~~~~~~~~~~~~~~~~~~~~^
        statement,
        ^^^^^^^^^^
        params,
        ^^^^^^^
        execution_options={"_sa_orm_load_options": self.load_options},
        ^^^^^^^^^^^^^^^^^^^^^^^^^^^^^^^^^^^^^^^^^^^^^^^^^^^^^^^^^^^^^^
    )
    ^
  File "C:\Users\dshan\portility\backend\venv\Lib\site-packages\sqlalchemy\orm\session.py", line 2351, in execute
    return self._execute_internal(
           ~~~~~~~~~~~~~~~~~~~~~~^
        statement,
        ^^^^^^^^^^
    ...<4 lines>...
        _add_event=_add_event,
        ^^^^^^^^^^^^^^^^^^^^^^
    )
    ^
  File "C:\Users\dshan\portility\backend\venv\Lib\site-packages\sqlalchemy\orm\session.py", line 2249, in _execute_internal
    result: Result[Any] = compile_state_cls.orm_execute_statement(
                          ~~~~~~~~~~~~~~~~~~~~~~~~~~~~~~~~~~~~~~~^
        self,
        ^^^^^
    ...<4 lines>...
        conn,
        ^^^^^
    )
    ^
  File "C:\Users\dshan\portility\backend\venv\Lib\site-packages\sqlalchemy\orm\context.py", line 306, in orm_execute_statement
    result = conn.execute(
        statement, params or {}, execution_options=execution_options
    )
  File "C:\Users\dshan\portility\backend\venv\Lib\site-packages\sqlalchemy\engine\base.py", line 1419, in execute
    return meth(
        self,
        distilled_parameters,
        execution_options or NO_OPTIONS,
    )
  File "C:\Users\dshan\portility\backend\venv\Lib\site-packages\sqlalchemy\sql\elements.py", line 526, in _execute_on_connection
    return connection._execute_clauseelement(
           ~~~~~~~~~~~~~~~~~~~~~~~~~~~~~~~~~^
        self, distilled_params, execution_options
        ^^^^^^^^^^^^^^^^^^^^^^^^^^^^^^^^^^^^^^^^^
    )
    ^
  File "C:\Users\dshan\portility\backend\venv\Lib\site-packages\sqlalchemy\engine\base.py", line 1641, in _execute_clauseelement
    ret = self._execute_context(
        dialect,
    ...<8 lines>...
        cache_hit=cache_hit,
    )
  File "C:\Users\dshan\portility\backend\venv\Lib\site-packages\sqlalchemy\engine\base.py", line 1846, in _execute_context
    return self._exec_single_context(
           ~~~~~~~~~~~~~~~~~~~~~~~~~^
        dialect, context, statement, parameters
        ^^^^^^^^^^^^^^^^^^^^^^^^^^^^^^^^^^^^^^^
    )
    ^
  File "C:\Users\dshan\portility\backend\venv\Lib\site-packages\sqlalchemy\engine\base.py", line 1986, in _exec_single_context
    self._handle_dbapi_exception(
    ~~~~~~~~~~~~~~~~~~~~~~~~~~~~^
        e, str_statement, effective_parameters, cursor, context
        ^^^^^^^^^^^^^^^^^^^^^^^^^^^^^^^^^^^^^^^^^^^^^^^^^^^^^^^
    )
    ^
  File "C:\Users\dshan\portility\backend\venv\Lib\site-packages\sqlalchemy\engine\base.py", line 2355, in _handle_dbapi_exception
    raise sqlalchemy_exception.with_traceback(exc_info[2]) from e
  File "C:\Users\dshan\portility\backend\venv\Lib\site-packages\sqlalchemy\engine\base.py", line 1967, in _exec_single_context
    self.dialect.do_execute(
    ~~~~~~~~~~~~~~~~~~~~~~~^
        cursor, str_statement, effective_parameters, context
        ^^^^^^^^^^^^^^^^^^^^^^^^^^^^^^^^^^^^^^^^^^^^^^^^^^^^
    )
    ^
  File "C:\Users\dshan\portility\backend\venv\Lib\site-packages\sqlalchemy\engine\default.py", line 951, in do_execute
    cursor.execute(statement, parameters)
    ~~~~~~~~~~~~~~^^^^^^^^^^^^^^^^^^^^^^^
sqlalchemy.exc.OperationalError: (sqlite3.OperationalError) no such table: tasks
[SQL: SELECT tasks.id AS tasks_id, tasks.title AS tasks_title, tasks.description AS tasks_description, tasks.status AS tasks_status, tasks.due_date AS tasks_due_date, tasks.created_at AS tasks_created_at, tasks.updated_at AS tasks_updated_at 
FROM tasks ORDER BY tasks.created_at DESC]
(Background on this error at: https://sqlalche.me/e/20/e3q8)
2025-10-21 19:41:57,980 [INFO] Registered tasks blueprint at /api/v1/tasks
2025-10-21 19:42:18,107 [INFO] Registered tasks blueprint at /api/v1/tasks
2025-10-21 19:42:19,506 [INFO] Registered tasks blueprint at /api/v1/tasks
2025-10-21 19:42:39,848 [INFO] GET /api/v1/tasks/ - from 127.0.0.1
2025-10-21 19:42:39,865 [ERROR] Unhandled exception: (sqlite3.OperationalError) no such table: tasks
[SQL: SELECT tasks.id AS tasks_id, tasks.title AS tasks_title, tasks.description AS tasks_description, tasks.status AS tasks_status, tasks.due_date AS tasks_due_date, tasks.created_at AS tasks_created_at, tasks.updated_at AS tasks_updated_at 
FROM tasks ORDER BY tasks.created_at DESC]
(Background on this error at: https://sqlalche.me/e/20/e3q8)
Traceback (most recent call last):
  File "C:\Users\dshan\portility\backend\venv\Lib\site-packages\sqlalchemy\engine\base.py", line 1967, in _exec_single_context
    self.dialect.do_execute(
    ~~~~~~~~~~~~~~~~~~~~~~~^
        cursor, str_statement, effective_parameters, context
        ^^^^^^^^^^^^^^^^^^^^^^^^^^^^^^^^^^^^^^^^^^^^^^^^^^^^
    )
    ^
  File "C:\Users\dshan\portility\backend\venv\Lib\site-packages\sqlalchemy\engine\default.py", line 951, in do_execute
    cursor.execute(statement, parameters)
    ~~~~~~~~~~~~~~^^^^^^^^^^^^^^^^^^^^^^^
sqlite3.OperationalError: no such table: tasks

The above exception was the direct cause of the following exception:

Traceback (most recent call last):
  File "C:\Users\dshan\portility\backend\venv\Lib\site-packages\flask\app.py", line 917, in full_dispatch_request
    rv = self.dispatch_request()
  File "C:\Users\dshan\portility\backend\venv\Lib\site-packages\flask\app.py", line 902, in dispatch_request
    return self.ensure_sync(self.view_functions[rule.endpoint])(**view_args)  # type: ignore[no-any-return]
           ~~~~~~~~~~~~~~~~~~~~~~~~~~~~~~~~~~~~~~~~~~~~~~~~~~~~^^^^^^^^^^^^^
  File "C:\Users\dshan\portility\backend\tasks\routes.py", line 12, in api_get_tasks
    all_tasks = get_tasks()
  File "C:\Users\dshan\portility\backend\tasks_store_sql.py", line 7, in get_tasks
    rows = Task.query.order_by(Task.created_at.desc()).all()
  File "C:\Users\dshan\portility\backend\venv\Lib\site-packages\sqlalchemy\orm\query.py", line 2704, in all
    return self._iter().all()  # type: ignore
           ~~~~~~~~~~^^
  File "C:\Users\dshan\portility\backend\venv\Lib\site-packages\sqlalchemy\orm\query.py", line 2857, in _iter
    result: Union[ScalarResult[_T], Result[_T]] = self.session.execute(
                                                  ~~~~~~~~~~~~~~~~~~~~^
        statement,
        ^^^^^^^^^^
        params,
        ^^^^^^^
        execution_options={"_sa_orm_load_options": self.load_options},
        ^^^^^^^^^^^^^^^^^^^^^^^^^^^^^^^^^^^^^^^^^^^^^^^^^^^^^^^^^^^^^^
    )
    ^
  File "C:\Users\dshan\portility\backend\venv\Lib\site-packages\sqlalchemy\orm\session.py", line 2351, in execute
    return self._execute_internal(
           ~~~~~~~~~~~~~~~~~~~~~~^
        statement,
        ^^^^^^^^^^
    ...<4 lines>...
        _add_event=_add_event,
        ^^^^^^^^^^^^^^^^^^^^^^
    )
    ^
  File "C:\Users\dshan\portility\backend\venv\Lib\site-packages\sqlalchemy\orm\session.py", line 2249, in _execute_internal
    result: Result[Any] = compile_state_cls.orm_execute_statement(
                          ~~~~~~~~~~~~~~~~~~~~~~~~~~~~~~~~~~~~~~~^
        self,
        ^^^^^
    ...<4 lines>...
        conn,
        ^^^^^
    )
    ^
  File "C:\Users\dshan\portility\backend\venv\Lib\site-packages\sqlalchemy\orm\context.py", line 306, in orm_execute_statement
    result = conn.execute(
        statement, params or {}, execution_options=execution_options
    )
  File "C:\Users\dshan\portility\backend\venv\Lib\site-packages\sqlalchemy\engine\base.py", line 1419, in execute
    return meth(
        self,
        distilled_parameters,
        execution_options or NO_OPTIONS,
    )
  File "C:\Users\dshan\portility\backend\venv\Lib\site-packages\sqlalchemy\sql\elements.py", line 526, in _execute_on_connection
    return connection._execute_clauseelement(
           ~~~~~~~~~~~~~~~~~~~~~~~~~~~~~~~~~^
        self, distilled_params, execution_options
        ^^^^^^^^^^^^^^^^^^^^^^^^^^^^^^^^^^^^^^^^^
    )
    ^
  File "C:\Users\dshan\portility\backend\venv\Lib\site-packages\sqlalchemy\engine\base.py", line 1641, in _execute_clauseelement
    ret = self._execute_context(
        dialect,
    ...<8 lines>...
        cache_hit=cache_hit,
    )
  File "C:\Users\dshan\portility\backend\venv\Lib\site-packages\sqlalchemy\engine\base.py", line 1846, in _execute_context
    return self._exec_single_context(
           ~~~~~~~~~~~~~~~~~~~~~~~~~^
        dialect, context, statement, parameters
        ^^^^^^^^^^^^^^^^^^^^^^^^^^^^^^^^^^^^^^^
    )
    ^
  File "C:\Users\dshan\portility\backend\venv\Lib\site-packages\sqlalchemy\engine\base.py", line 1986, in _exec_single_context
    self._handle_dbapi_exception(
    ~~~~~~~~~~~~~~~~~~~~~~~~~~~~^
        e, str_statement, effective_parameters, cursor, context
        ^^^^^^^^^^^^^^^^^^^^^^^^^^^^^^^^^^^^^^^^^^^^^^^^^^^^^^^
    )
    ^
  File "C:\Users\dshan\portility\backend\venv\Lib\site-packages\sqlalchemy\engine\base.py", line 2355, in _handle_dbapi_exception
    raise sqlalchemy_exception.with_traceback(exc_info[2]) from e
  File "C:\Users\dshan\portility\backend\venv\Lib\site-packages\sqlalchemy\engine\base.py", line 1967, in _exec_single_context
    self.dialect.do_execute(
    ~~~~~~~~~~~~~~~~~~~~~~~^
        cursor, str_statement, effective_parameters, context
        ^^^^^^^^^^^^^^^^^^^^^^^^^^^^^^^^^^^^^^^^^^^^^^^^^^^^
    )
    ^
  File "C:\Users\dshan\portility\backend\venv\Lib\site-packages\sqlalchemy\engine\default.py", line 951, in do_execute
    cursor.execute(statement, parameters)
    ~~~~~~~~~~~~~~^^^^^^^^^^^^^^^^^^^^^^^
sqlalchemy.exc.OperationalError: (sqlite3.OperationalError) no such table: tasks
[SQL: SELECT tasks.id AS tasks_id, tasks.title AS tasks_title, tasks.description AS tasks_description, tasks.status AS tasks_status, tasks.due_date AS tasks_due_date, tasks.created_at AS tasks_created_at, tasks.updated_at AS tasks_updated_at 
FROM tasks ORDER BY tasks.created_at DESC]
(Background on this error at: https://sqlalche.me/e/20/e3q8)
2025-10-21 19:42:39,930 [INFO] GET /api/v1/tasks/ - from 127.0.0.1
2025-10-21 19:42:39,938 [ERROR] Unhandled exception: (sqlite3.OperationalError) no such table: tasks
[SQL: SELECT tasks.id AS tasks_id, tasks.title AS tasks_title, tasks.description AS tasks_description, tasks.status AS tasks_status, tasks.due_date AS tasks_due_date, tasks.created_at AS tasks_created_at, tasks.updated_at AS tasks_updated_at 
FROM tasks ORDER BY tasks.created_at DESC]
(Background on this error at: https://sqlalche.me/e/20/e3q8)
Traceback (most recent call last):
  File "C:\Users\dshan\portility\backend\venv\Lib\site-packages\sqlalchemy\engine\base.py", line 1967, in _exec_single_context
    self.dialect.do_execute(
    ~~~~~~~~~~~~~~~~~~~~~~~^
        cursor, str_statement, effective_parameters, context
        ^^^^^^^^^^^^^^^^^^^^^^^^^^^^^^^^^^^^^^^^^^^^^^^^^^^^
    )
    ^
  File "C:\Users\dshan\portility\backend\venv\Lib\site-packages\sqlalchemy\engine\default.py", line 951, in do_execute
    cursor.execute(statement, parameters)
    ~~~~~~~~~~~~~~^^^^^^^^^^^^^^^^^^^^^^^
sqlite3.OperationalError: no such table: tasks

The above exception was the direct cause of the following exception:

Traceback (most recent call last):
  File "C:\Users\dshan\portility\backend\venv\Lib\site-packages\flask\app.py", line 917, in full_dispatch_request
    rv = self.dispatch_request()
  File "C:\Users\dshan\portility\backend\venv\Lib\site-packages\flask\app.py", line 902, in dispatch_request
    return self.ensure_sync(self.view_functions[rule.endpoint])(**view_args)  # type: ignore[no-any-return]
           ~~~~~~~~~~~~~~~~~~~~~~~~~~~~~~~~~~~~~~~~~~~~~~~~~~~~^^^^^^^^^^^^^
  File "C:\Users\dshan\portility\backend\tasks\routes.py", line 12, in api_get_tasks
    all_tasks = get_tasks()
  File "C:\Users\dshan\portility\backend\tasks_store_sql.py", line 7, in get_tasks
    rows = Task.query.order_by(Task.created_at.desc()).all()
  File "C:\Users\dshan\portility\backend\venv\Lib\site-packages\sqlalchemy\orm\query.py", line 2704, in all
    return self._iter().all()  # type: ignore
           ~~~~~~~~~~^^
  File "C:\Users\dshan\portility\backend\venv\Lib\site-packages\sqlalchemy\orm\query.py", line 2857, in _iter
    result: Union[ScalarResult[_T], Result[_T]] = self.session.execute(
                                                  ~~~~~~~~~~~~~~~~~~~~^
        statement,
        ^^^^^^^^^^
        params,
        ^^^^^^^
        execution_options={"_sa_orm_load_options": self.load_options},
        ^^^^^^^^^^^^^^^^^^^^^^^^^^^^^^^^^^^^^^^^^^^^^^^^^^^^^^^^^^^^^^
    )
    ^
  File "C:\Users\dshan\portility\backend\venv\Lib\site-packages\sqlalchemy\orm\session.py", line 2351, in execute
    return self._execute_internal(
           ~~~~~~~~~~~~~~~~~~~~~~^
        statement,
        ^^^^^^^^^^
    ...<4 lines>...
        _add_event=_add_event,
        ^^^^^^^^^^^^^^^^^^^^^^
    )
    ^
  File "C:\Users\dshan\portility\backend\venv\Lib\site-packages\sqlalchemy\orm\session.py", line 2249, in _execute_internal
    result: Result[Any] = compile_state_cls.orm_execute_statement(
                          ~~~~~~~~~~~~~~~~~~~~~~~~~~~~~~~~~~~~~~~^
        self,
        ^^^^^
    ...<4 lines>...
        conn,
        ^^^^^
    )
    ^
  File "C:\Users\dshan\portility\backend\venv\Lib\site-packages\sqlalchemy\orm\context.py", line 306, in orm_execute_statement
    result = conn.execute(
        statement, params or {}, execution_options=execution_options
    )
  File "C:\Users\dshan\portility\backend\venv\Lib\site-packages\sqlalchemy\engine\base.py", line 1419, in execute
    return meth(
        self,
        distilled_parameters,
        execution_options or NO_OPTIONS,
    )
  File "C:\Users\dshan\portility\backend\venv\Lib\site-packages\sqlalchemy\sql\elements.py", line 526, in _execute_on_connection
    return connection._execute_clauseelement(
           ~~~~~~~~~~~~~~~~~~~~~~~~~~~~~~~~~^
        self, distilled_params, execution_options
        ^^^^^^^^^^^^^^^^^^^^^^^^^^^^^^^^^^^^^^^^^
    )
    ^
  File "C:\Users\dshan\portility\backend\venv\Lib\site-packages\sqlalchemy\engine\base.py", line 1641, in _execute_clauseelement
    ret = self._execute_context(
        dialect,
    ...<8 lines>...
        cache_hit=cache_hit,
    )
  File "C:\Users\dshan\portility\backend\venv\Lib\site-packages\sqlalchemy\engine\base.py", line 1846, in _execute_context
    return self._exec_single_context(
           ~~~~~~~~~~~~~~~~~~~~~~~~~^
        dialect, context, statement, parameters
        ^^^^^^^^^^^^^^^^^^^^^^^^^^^^^^^^^^^^^^^
    )
    ^
  File "C:\Users\dshan\portility\backend\venv\Lib\site-packages\sqlalchemy\engine\base.py", line 1986, in _exec_single_context
    self._handle_dbapi_exception(
    ~~~~~~~~~~~~~~~~~~~~~~~~~~~~^
        e, str_statement, effective_parameters, cursor, context
        ^^^^^^^^^^^^^^^^^^^^^^^^^^^^^^^^^^^^^^^^^^^^^^^^^^^^^^^
    )
    ^
  File "C:\Users\dshan\portility\backend\venv\Lib\site-packages\sqlalchemy\engine\base.py", line 2355, in _handle_dbapi_exception
    raise sqlalchemy_exception.with_traceback(exc_info[2]) from e
  File "C:\Users\dshan\portility\backend\venv\Lib\site-packages\sqlalchemy\engine\base.py", line 1967, in _exec_single_context
    self.dialect.do_execute(
    ~~~~~~~~~~~~~~~~~~~~~~~^
        cursor, str_statement, effective_parameters, context
        ^^^^^^^^^^^^^^^^^^^^^^^^^^^^^^^^^^^^^^^^^^^^^^^^^^^^
    )
    ^
  File "C:\Users\dshan\portility\backend\venv\Lib\site-packages\sqlalchemy\engine\default.py", line 951, in do_execute
    cursor.execute(statement, parameters)
    ~~~~~~~~~~~~~~^^^^^^^^^^^^^^^^^^^^^^^
sqlalchemy.exc.OperationalError: (sqlite3.OperationalError) no such table: tasks
[SQL: SELECT tasks.id AS tasks_id, tasks.title AS tasks_title, tasks.description AS tasks_description, tasks.status AS tasks_status, tasks.due_date AS tasks_due_date, tasks.created_at AS tasks_created_at, tasks.updated_at AS tasks_updated_at 
FROM tasks ORDER BY tasks.created_at DESC]
(Background on this error at: https://sqlalche.me/e/20/e3q8)
2025-10-21 19:42:58,476 [INFO] GET /api/ping - from 127.0.0.1
2025-10-21 20:43:19,862 [INFO] GET /api/v1/tasks/ - from 127.0.0.1
2025-10-21 20:43:19,890 [ERROR] Unhandled exception: (sqlite3.OperationalError) no such table: tasks
[SQL: SELECT tasks.id AS tasks_id, tasks.title AS tasks_title, tasks.description AS tasks_description, tasks.status AS tasks_status, tasks.due_date AS tasks_due_date, tasks.created_at AS tasks_created_at, tasks.updated_at AS tasks_updated_at 
FROM tasks ORDER BY tasks.created_at DESC]
(Background on this error at: https://sqlalche.me/e/20/e3q8)
Traceback (most recent call last):
  File "C:\Users\dshan\portility\backend\venv\Lib\site-packages\sqlalchemy\engine\base.py", line 1967, in _exec_single_context
    self.dialect.do_execute(
    ~~~~~~~~~~~~~~~~~~~~~~~^
        cursor, str_statement, effective_parameters, context
        ^^^^^^^^^^^^^^^^^^^^^^^^^^^^^^^^^^^^^^^^^^^^^^^^^^^^
    )
    ^
  File "C:\Users\dshan\portility\backend\venv\Lib\site-packages\sqlalchemy\engine\default.py", line 951, in do_execute
    cursor.execute(statement, parameters)
    ~~~~~~~~~~~~~~^^^^^^^^^^^^^^^^^^^^^^^
sqlite3.OperationalError: no such table: tasks

The above exception was the direct cause of the following exception:

Traceback (most recent call last):
  File "C:\Users\dshan\portility\backend\venv\Lib\site-packages\flask\app.py", line 917, in full_dispatch_request
    rv = self.dispatch_request()
  File "C:\Users\dshan\portility\backend\venv\Lib\site-packages\flask\app.py", line 902, in dispatch_request
    return self.ensure_sync(self.view_functions[rule.endpoint])(**view_args)  # type: ignore[no-any-return]
           ~~~~~~~~~~~~~~~~~~~~~~~~~~~~~~~~~~~~~~~~~~~~~~~~~~~~^^^^^^^^^^^^^
  File "C:\Users\dshan\portility\backend\tasks\routes.py", line 12, in api_get_tasks
    all_tasks = get_tasks()
  File "C:\Users\dshan\portility\backend\tasks_store_sql.py", line 7, in get_tasks
    rows = Task.query.order_by(Task.created_at.desc()).all()
  File "C:\Users\dshan\portility\backend\venv\Lib\site-packages\sqlalchemy\orm\query.py", line 2704, in all
    return self._iter().all()  # type: ignore
           ~~~~~~~~~~^^
  File "C:\Users\dshan\portility\backend\venv\Lib\site-packages\sqlalchemy\orm\query.py", line 2857, in _iter
    result: Union[ScalarResult[_T], Result[_T]] = self.session.execute(
                                                  ~~~~~~~~~~~~~~~~~~~~^
        statement,
        ^^^^^^^^^^
        params,
        ^^^^^^^
        execution_options={"_sa_orm_load_options": self.load_options},
        ^^^^^^^^^^^^^^^^^^^^^^^^^^^^^^^^^^^^^^^^^^^^^^^^^^^^^^^^^^^^^^
    )
    ^
  File "C:\Users\dshan\portility\backend\venv\Lib\site-packages\sqlalchemy\orm\session.py", line 2351, in execute
    return self._execute_internal(
           ~~~~~~~~~~~~~~~~~~~~~~^
        statement,
        ^^^^^^^^^^
    ...<4 lines>...
        _add_event=_add_event,
        ^^^^^^^^^^^^^^^^^^^^^^
    )
    ^
  File "C:\Users\dshan\portility\backend\venv\Lib\site-packages\sqlalchemy\orm\session.py", line 2249, in _execute_internal
    result: Result[Any] = compile_state_cls.orm_execute_statement(
                          ~~~~~~~~~~~~~~~~~~~~~~~~~~~~~~~~~~~~~~~^
        self,
        ^^^^^
    ...<4 lines>...
        conn,
        ^^^^^
    )
    ^
  File "C:\Users\dshan\portility\backend\venv\Lib\site-packages\sqlalchemy\orm\context.py", line 306, in orm_execute_statement
    result = conn.execute(
        statement, params or {}, execution_options=execution_options
    )
  File "C:\Users\dshan\portility\backend\venv\Lib\site-packages\sqlalchemy\engine\base.py", line 1419, in execute
    return meth(
        self,
        distilled_parameters,
        execution_options or NO_OPTIONS,
    )
  File "C:\Users\dshan\portility\backend\venv\Lib\site-packages\sqlalchemy\sql\elements.py", line 526, in _execute_on_connection
    return connection._execute_clauseelement(
           ~~~~~~~~~~~~~~~~~~~~~~~~~~~~~~~~~^
        self, distilled_params, execution_options
        ^^^^^^^^^^^^^^^^^^^^^^^^^^^^^^^^^^^^^^^^^
    )
    ^
  File "C:\Users\dshan\portility\backend\venv\Lib\site-packages\sqlalchemy\engine\base.py", line 1641, in _execute_clauseelement
    ret = self._execute_context(
        dialect,
    ...<8 lines>...
        cache_hit=cache_hit,
    )
  File "C:\Users\dshan\portility\backend\venv\Lib\site-packages\sqlalchemy\engine\base.py", line 1846, in _execute_context
    return self._exec_single_context(
           ~~~~~~~~~~~~~~~~~~~~~~~~~^
        dialect, context, statement, parameters
        ^^^^^^^^^^^^^^^^^^^^^^^^^^^^^^^^^^^^^^^
    )
    ^
  File "C:\Users\dshan\portility\backend\venv\Lib\site-packages\sqlalchemy\engine\base.py", line 1986, in _exec_single_context
    self._handle_dbapi_exception(
    ~~~~~~~~~~~~~~~~~~~~~~~~~~~~^
        e, str_statement, effective_parameters, cursor, context
        ^^^^^^^^^^^^^^^^^^^^^^^^^^^^^^^^^^^^^^^^^^^^^^^^^^^^^^^
    )
    ^
  File "C:\Users\dshan\portility\backend\venv\Lib\site-packages\sqlalchemy\engine\base.py", line 2355, in _handle_dbapi_exception
    raise sqlalchemy_exception.with_traceback(exc_info[2]) from e
  File "C:\Users\dshan\portility\backend\venv\Lib\site-packages\sqlalchemy\engine\base.py", line 1967, in _exec_single_context
    self.dialect.do_execute(
    ~~~~~~~~~~~~~~~~~~~~~~~^
        cursor, str_statement, effective_parameters, context
        ^^^^^^^^^^^^^^^^^^^^^^^^^^^^^^^^^^^^^^^^^^^^^^^^^^^^
    )
    ^
  File "C:\Users\dshan\portility\backend\venv\Lib\site-packages\sqlalchemy\engine\default.py", line 951, in do_execute
    cursor.execute(statement, parameters)
    ~~~~~~~~~~~~~~^^^^^^^^^^^^^^^^^^^^^^^
sqlalchemy.exc.OperationalError: (sqlite3.OperationalError) no such table: tasks
[SQL: SELECT tasks.id AS tasks_id, tasks.title AS tasks_title, tasks.description AS tasks_description, tasks.status AS tasks_status, tasks.due_date AS tasks_due_date, tasks.created_at AS tasks_created_at, tasks.updated_at AS tasks_updated_at 
FROM tasks ORDER BY tasks.created_at DESC]
(Background on this error at: https://sqlalche.me/e/20/e3q8)
2025-10-21 20:43:20,079 [INFO] GET /api/v1/tasks/ - from 127.0.0.1
2025-10-21 20:43:20,080 [ERROR] Unhandled exception: (sqlite3.OperationalError) no such table: tasks
[SQL: SELECT tasks.id AS tasks_id, tasks.title AS tasks_title, tasks.description AS tasks_description, tasks.status AS tasks_status, tasks.due_date AS tasks_due_date, tasks.created_at AS tasks_created_at, tasks.updated_at AS tasks_updated_at 
FROM tasks ORDER BY tasks.created_at DESC]
(Background on this error at: https://sqlalche.me/e/20/e3q8)
Traceback (most recent call last):
  File "C:\Users\dshan\portility\backend\venv\Lib\site-packages\sqlalchemy\engine\base.py", line 1967, in _exec_single_context
    self.dialect.do_execute(
    ~~~~~~~~~~~~~~~~~~~~~~~^
        cursor, str_statement, effective_parameters, context
        ^^^^^^^^^^^^^^^^^^^^^^^^^^^^^^^^^^^^^^^^^^^^^^^^^^^^
    )
    ^
  File "C:\Users\dshan\portility\backend\venv\Lib\site-packages\sqlalchemy\engine\default.py", line 951, in do_execute
    cursor.execute(statement, parameters)
    ~~~~~~~~~~~~~~^^^^^^^^^^^^^^^^^^^^^^^
sqlite3.OperationalError: no such table: tasks

The above exception was the direct cause of the following exception:

Traceback (most recent call last):
  File "C:\Users\dshan\portility\backend\venv\Lib\site-packages\flask\app.py", line 917, in full_dispatch_request
    rv = self.dispatch_request()
  File "C:\Users\dshan\portility\backend\venv\Lib\site-packages\flask\app.py", line 902, in dispatch_request
    return self.ensure_sync(self.view_functions[rule.endpoint])(**view_args)  # type: ignore[no-any-return]
           ~~~~~~~~~~~~~~~~~~~~~~~~~~~~~~~~~~~~~~~~~~~~~~~~~~~~^^^^^^^^^^^^^
  File "C:\Users\dshan\portility\backend\tasks\routes.py", line 12, in api_get_tasks
    all_tasks = get_tasks()
  File "C:\Users\dshan\portility\backend\tasks_store_sql.py", line 7, in get_tasks
    rows = Task.query.order_by(Task.created_at.desc()).all()
  File "C:\Users\dshan\portility\backend\venv\Lib\site-packages\sqlalchemy\orm\query.py", line 2704, in all
    return self._iter().all()  # type: ignore
           ~~~~~~~~~~^^
  File "C:\Users\dshan\portility\backend\venv\Lib\site-packages\sqlalchemy\orm\query.py", line 2857, in _iter
    result: Union[ScalarResult[_T], Result[_T]] = self.session.execute(
                                                  ~~~~~~~~~~~~~~~~~~~~^
        statement,
        ^^^^^^^^^^
        params,
        ^^^^^^^
        execution_options={"_sa_orm_load_options": self.load_options},
        ^^^^^^^^^^^^^^^^^^^^^^^^^^^^^^^^^^^^^^^^^^^^^^^^^^^^^^^^^^^^^^
    )
    ^
  File "C:\Users\dshan\portility\backend\venv\Lib\site-packages\sqlalchemy\orm\session.py", line 2351, in execute
    return self._execute_internal(
           ~~~~~~~~~~~~~~~~~~~~~~^
        statement,
        ^^^^^^^^^^
    ...<4 lines>...
        _add_event=_add_event,
        ^^^^^^^^^^^^^^^^^^^^^^
    )
    ^
  File "C:\Users\dshan\portility\backend\venv\Lib\site-packages\sqlalchemy\orm\session.py", line 2249, in _execute_internal
    result: Result[Any] = compile_state_cls.orm_execute_statement(
                          ~~~~~~~~~~~~~~~~~~~~~~~~~~~~~~~~~~~~~~~^
        self,
        ^^^^^
    ...<4 lines>...
        conn,
        ^^^^^
    )
    ^
  File "C:\Users\dshan\portility\backend\venv\Lib\site-packages\sqlalchemy\orm\context.py", line 306, in orm_execute_statement
    result = conn.execute(
        statement, params or {}, execution_options=execution_options
    )
  File "C:\Users\dshan\portility\backend\venv\Lib\site-packages\sqlalchemy\engine\base.py", line 1419, in execute
    return meth(
        self,
        distilled_parameters,
        execution_options or NO_OPTIONS,
    )
  File "C:\Users\dshan\portility\backend\venv\Lib\site-packages\sqlalchemy\sql\elements.py", line 526, in _execute_on_connection
    return connection._execute_clauseelement(
           ~~~~~~~~~~~~~~~~~~~~~~~~~~~~~~~~~^
        self, distilled_params, execution_options
        ^^^^^^^^^^^^^^^^^^^^^^^^^^^^^^^^^^^^^^^^^
    )
    ^
  File "C:\Users\dshan\portility\backend\venv\Lib\site-packages\sqlalchemy\engine\base.py", line 1641, in _execute_clauseelement
    ret = self._execute_context(
        dialect,
    ...<8 lines>...
        cache_hit=cache_hit,
    )
  File "C:\Users\dshan\portility\backend\venv\Lib\site-packages\sqlalchemy\engine\base.py", line 1846, in _execute_context
    return self._exec_single_context(
           ~~~~~~~~~~~~~~~~~~~~~~~~~^
        dialect, context, statement, parameters
        ^^^^^^^^^^^^^^^^^^^^^^^^^^^^^^^^^^^^^^^
    )
    ^
  File "C:\Users\dshan\portility\backend\venv\Lib\site-packages\sqlalchemy\engine\base.py", line 1986, in _exec_single_context
    self._handle_dbapi_exception(
    ~~~~~~~~~~~~~~~~~~~~~~~~~~~~^
        e, str_statement, effective_parameters, cursor, context
        ^^^^^^^^^^^^^^^^^^^^^^^^^^^^^^^^^^^^^^^^^^^^^^^^^^^^^^^
    )
    ^
  File "C:\Users\dshan\portility\backend\venv\Lib\site-packages\sqlalchemy\engine\base.py", line 2355, in _handle_dbapi_exception
    raise sqlalchemy_exception.with_traceback(exc_info[2]) from e
  File "C:\Users\dshan\portility\backend\venv\Lib\site-packages\sqlalchemy\engine\base.py", line 1967, in _exec_single_context
    self.dialect.do_execute(
    ~~~~~~~~~~~~~~~~~~~~~~~^
        cursor, str_statement, effective_parameters, context
        ^^^^^^^^^^^^^^^^^^^^^^^^^^^^^^^^^^^^^^^^^^^^^^^^^^^^
    )
    ^
  File "C:\Users\dshan\portility\backend\venv\Lib\site-packages\sqlalchemy\engine\default.py", line 951, in do_execute
    cursor.execute(statement, parameters)
    ~~~~~~~~~~~~~~^^^^^^^^^^^^^^^^^^^^^^^
sqlalchemy.exc.OperationalError: (sqlite3.OperationalError) no such table: tasks
[SQL: SELECT tasks.id AS tasks_id, tasks.title AS tasks_title, tasks.description AS tasks_description, tasks.status AS tasks_status, tasks.due_date AS tasks_due_date, tasks.created_at AS tasks_created_at, tasks.updated_at AS tasks_updated_at 
FROM tasks ORDER BY tasks.created_at DESC]
(Background on this error at: https://sqlalche.me/e/20/e3q8)
2025-10-21 21:18:23,204 [INFO] GET /api/v1/tasks/ - from 127.0.0.1
2025-10-21 21:18:23,210 [ERROR] Unhandled exception: (sqlite3.OperationalError) no such table: tasks
[SQL: SELECT tasks.id AS tasks_id, tasks.title AS tasks_title, tasks.description AS tasks_description, tasks.status AS tasks_status, tasks.due_date AS tasks_due_date, tasks.created_at AS tasks_created_at, tasks.updated_at AS tasks_updated_at 
FROM tasks ORDER BY tasks.created_at DESC]
(Background on this error at: https://sqlalche.me/e/20/e3q8)
Traceback (most recent call last):
  File "C:\Users\dshan\portility\backend\venv\Lib\site-packages\sqlalchemy\engine\base.py", line 1967, in _exec_single_context
    self.dialect.do_execute(
    ~~~~~~~~~~~~~~~~~~~~~~~^
        cursor, str_statement, effective_parameters, context
        ^^^^^^^^^^^^^^^^^^^^^^^^^^^^^^^^^^^^^^^^^^^^^^^^^^^^
    )
    ^
  File "C:\Users\dshan\portility\backend\venv\Lib\site-packages\sqlalchemy\engine\default.py", line 951, in do_execute
    cursor.execute(statement, parameters)
    ~~~~~~~~~~~~~~^^^^^^^^^^^^^^^^^^^^^^^
sqlite3.OperationalError: no such table: tasks

The above exception was the direct cause of the following exception:

Traceback (most recent call last):
  File "C:\Users\dshan\portility\backend\venv\Lib\site-packages\flask\app.py", line 917, in full_dispatch_request
    rv = self.dispatch_request()
  File "C:\Users\dshan\portility\backend\venv\Lib\site-packages\flask\app.py", line 902, in dispatch_request
    return self.ensure_sync(self.view_functions[rule.endpoint])(**view_args)  # type: ignore[no-any-return]
           ~~~~~~~~~~~~~~~~~~~~~~~~~~~~~~~~~~~~~~~~~~~~~~~~~~~~^^^^^^^^^^^^^
  File "C:\Users\dshan\portility\backend\tasks\routes.py", line 12, in api_get_tasks
    all_tasks = get_tasks()
  File "C:\Users\dshan\portility\backend\tasks_store_sql.py", line 7, in get_tasks
    rows = Task.query.order_by(Task.created_at.desc()).all()
  File "C:\Users\dshan\portility\backend\venv\Lib\site-packages\sqlalchemy\orm\query.py", line 2704, in all
    return self._iter().all()  # type: ignore
           ~~~~~~~~~~^^
  File "C:\Users\dshan\portility\backend\venv\Lib\site-packages\sqlalchemy\orm\query.py", line 2857, in _iter
    result: Union[ScalarResult[_T], Result[_T]] = self.session.execute(
                                                  ~~~~~~~~~~~~~~~~~~~~^
        statement,
        ^^^^^^^^^^
        params,
        ^^^^^^^
        execution_options={"_sa_orm_load_options": self.load_options},
        ^^^^^^^^^^^^^^^^^^^^^^^^^^^^^^^^^^^^^^^^^^^^^^^^^^^^^^^^^^^^^^
    )
    ^
  File "C:\Users\dshan\portility\backend\venv\Lib\site-packages\sqlalchemy\orm\session.py", line 2351, in execute
    return self._execute_internal(
           ~~~~~~~~~~~~~~~~~~~~~~^
        statement,
        ^^^^^^^^^^
    ...<4 lines>...
        _add_event=_add_event,
        ^^^^^^^^^^^^^^^^^^^^^^
    )
    ^
  File "C:\Users\dshan\portility\backend\venv\Lib\site-packages\sqlalchemy\orm\session.py", line 2249, in _execute_internal
    result: Result[Any] = compile_state_cls.orm_execute_statement(
                          ~~~~~~~~~~~~~~~~~~~~~~~~~~~~~~~~~~~~~~~^
        self,
        ^^^^^
    ...<4 lines>...
        conn,
        ^^^^^
    )
    ^
  File "C:\Users\dshan\portility\backend\venv\Lib\site-packages\sqlalchemy\orm\context.py", line 306, in orm_execute_statement
    result = conn.execute(
        statement, params or {}, execution_options=execution_options
    )
  File "C:\Users\dshan\portility\backend\venv\Lib\site-packages\sqlalchemy\engine\base.py", line 1419, in execute
    return meth(
        self,
        distilled_parameters,
        execution_options or NO_OPTIONS,
    )
  File "C:\Users\dshan\portility\backend\venv\Lib\site-packages\sqlalchemy\sql\elements.py", line 526, in _execute_on_connection
    return connection._execute_clauseelement(
           ~~~~~~~~~~~~~~~~~~~~~~~~~~~~~~~~~^
        self, distilled_params, execution_options
        ^^^^^^^^^^^^^^^^^^^^^^^^^^^^^^^^^^^^^^^^^
    )
    ^
  File "C:\Users\dshan\portility\backend\venv\Lib\site-packages\sqlalchemy\engine\base.py", line 1641, in _execute_clauseelement
    ret = self._execute_context(
        dialect,
    ...<8 lines>...
        cache_hit=cache_hit,
    )
  File "C:\Users\dshan\portility\backend\venv\Lib\site-packages\sqlalchemy\engine\base.py", line 1846, in _execute_context
    return self._exec_single_context(
           ~~~~~~~~~~~~~~~~~~~~~~~~~^
        dialect, context, statement, parameters
        ^^^^^^^^^^^^^^^^^^^^^^^^^^^^^^^^^^^^^^^
    )
    ^
  File "C:\Users\dshan\portility\backend\venv\Lib\site-packages\sqlalchemy\engine\base.py", line 1986, in _exec_single_context
    self._handle_dbapi_exception(
    ~~~~~~~~~~~~~~~~~~~~~~~~~~~~^
        e, str_statement, effective_parameters, cursor, context
        ^^^^^^^^^^^^^^^^^^^^^^^^^^^^^^^^^^^^^^^^^^^^^^^^^^^^^^^
    )
    ^
  File "C:\Users\dshan\portility\backend\venv\Lib\site-packages\sqlalchemy\engine\base.py", line 2355, in _handle_dbapi_exception
    raise sqlalchemy_exception.with_traceback(exc_info[2]) from e
  File "C:\Users\dshan\portility\backend\venv\Lib\site-packages\sqlalchemy\engine\base.py", line 1967, in _exec_single_context
    self.dialect.do_execute(
    ~~~~~~~~~~~~~~~~~~~~~~~^
        cursor, str_statement, effective_parameters, context
        ^^^^^^^^^^^^^^^^^^^^^^^^^^^^^^^^^^^^^^^^^^^^^^^^^^^^
    )
    ^
  File "C:\Users\dshan\portility\backend\venv\Lib\site-packages\sqlalchemy\engine\default.py", line 951, in do_execute
    cursor.execute(statement, parameters)
    ~~~~~~~~~~~~~~^^^^^^^^^^^^^^^^^^^^^^^
sqlalchemy.exc.OperationalError: (sqlite3.OperationalError) no such table: tasks
[SQL: SELECT tasks.id AS tasks_id, tasks.title AS tasks_title, tasks.description AS tasks_description, tasks.status AS tasks_status, tasks.due_date AS tasks_due_date, tasks.created_at AS tasks_created_at, tasks.updated_at AS tasks_updated_at 
FROM tasks ORDER BY tasks.created_at DESC]
(Background on this error at: https://sqlalche.me/e/20/e3q8)
2025-10-21 21:18:23,292 [INFO] GET /api/v1/tasks/ - from 127.0.0.1
2025-10-21 21:18:23,298 [ERROR] Unhandled exception: (sqlite3.OperationalError) no such table: tasks
[SQL: SELECT tasks.id AS tasks_id, tasks.title AS tasks_title, tasks.description AS tasks_description, tasks.status AS tasks_status, tasks.due_date AS tasks_due_date, tasks.created_at AS tasks_created_at, tasks.updated_at AS tasks_updated_at 
FROM tasks ORDER BY tasks.created_at DESC]
(Background on this error at: https://sqlalche.me/e/20/e3q8)
Traceback (most recent call last):
  File "C:\Users\dshan\portility\backend\venv\Lib\site-packages\sqlalchemy\engine\base.py", line 1967, in _exec_single_context
    self.dialect.do_execute(
    ~~~~~~~~~~~~~~~~~~~~~~~^
        cursor, str_statement, effective_parameters, context
        ^^^^^^^^^^^^^^^^^^^^^^^^^^^^^^^^^^^^^^^^^^^^^^^^^^^^
    )
    ^
  File "C:\Users\dshan\portility\backend\venv\Lib\site-packages\sqlalchemy\engine\default.py", line 951, in do_execute
    cursor.execute(statement, parameters)
    ~~~~~~~~~~~~~~^^^^^^^^^^^^^^^^^^^^^^^
sqlite3.OperationalError: no such table: tasks

The above exception was the direct cause of the following exception:

Traceback (most recent call last):
  File "C:\Users\dshan\portility\backend\venv\Lib\site-packages\flask\app.py", line 917, in full_dispatch_request
    rv = self.dispatch_request()
  File "C:\Users\dshan\portility\backend\venv\Lib\site-packages\flask\app.py", line 902, in dispatch_request
    return self.ensure_sync(self.view_functions[rule.endpoint])(**view_args)  # type: ignore[no-any-return]
           ~~~~~~~~~~~~~~~~~~~~~~~~~~~~~~~~~~~~~~~~~~~~~~~~~~~~^^^^^^^^^^^^^
  File "C:\Users\dshan\portility\backend\tasks\routes.py", line 12, in api_get_tasks
    all_tasks = get_tasks()
  File "C:\Users\dshan\portility\backend\tasks_store_sql.py", line 7, in get_tasks
    rows = Task.query.order_by(Task.created_at.desc()).all()
  File "C:\Users\dshan\portility\backend\venv\Lib\site-packages\sqlalchemy\orm\query.py", line 2704, in all
    return self._iter().all()  # type: ignore
           ~~~~~~~~~~^^
  File "C:\Users\dshan\portility\backend\venv\Lib\site-packages\sqlalchemy\orm\query.py", line 2857, in _iter
    result: Union[ScalarResult[_T], Result[_T]] = self.session.execute(
                                                  ~~~~~~~~~~~~~~~~~~~~^
        statement,
        ^^^^^^^^^^
        params,
        ^^^^^^^
        execution_options={"_sa_orm_load_options": self.load_options},
        ^^^^^^^^^^^^^^^^^^^^^^^^^^^^^^^^^^^^^^^^^^^^^^^^^^^^^^^^^^^^^^
    )
    ^
  File "C:\Users\dshan\portility\backend\venv\Lib\site-packages\sqlalchemy\orm\session.py", line 2351, in execute
    return self._execute_internal(
           ~~~~~~~~~~~~~~~~~~~~~~^
        statement,
        ^^^^^^^^^^
    ...<4 lines>...
        _add_event=_add_event,
        ^^^^^^^^^^^^^^^^^^^^^^
    )
    ^
  File "C:\Users\dshan\portility\backend\venv\Lib\site-packages\sqlalchemy\orm\session.py", line 2249, in _execute_internal
    result: Result[Any] = compile_state_cls.orm_execute_statement(
                          ~~~~~~~~~~~~~~~~~~~~~~~~~~~~~~~~~~~~~~~^
        self,
        ^^^^^
    ...<4 lines>...
        conn,
        ^^^^^
    )
    ^
  File "C:\Users\dshan\portility\backend\venv\Lib\site-packages\sqlalchemy\orm\context.py", line 306, in orm_execute_statement
    result = conn.execute(
        statement, params or {}, execution_options=execution_options
    )
  File "C:\Users\dshan\portility\backend\venv\Lib\site-packages\sqlalchemy\engine\base.py", line 1419, in execute
    return meth(
        self,
        distilled_parameters,
        execution_options or NO_OPTIONS,
    )
  File "C:\Users\dshan\portility\backend\venv\Lib\site-packages\sqlalchemy\sql\elements.py", line 526, in _execute_on_connection
    return connection._execute_clauseelement(
           ~~~~~~~~~~~~~~~~~~~~~~~~~~~~~~~~~^
        self, distilled_params, execution_options
        ^^^^^^^^^^^^^^^^^^^^^^^^^^^^^^^^^^^^^^^^^
    )
    ^
  File "C:\Users\dshan\portility\backend\venv\Lib\site-packages\sqlalchemy\engine\base.py", line 1641, in _execute_clauseelement
    ret = self._execute_context(
        dialect,
    ...<8 lines>...
        cache_hit=cache_hit,
    )
  File "C:\Users\dshan\portility\backend\venv\Lib\site-packages\sqlalchemy\engine\base.py", line 1846, in _execute_context
    return self._exec_single_context(
           ~~~~~~~~~~~~~~~~~~~~~~~~~^
        dialect, context, statement, parameters
        ^^^^^^^^^^^^^^^^^^^^^^^^^^^^^^^^^^^^^^^
    )
    ^
  File "C:\Users\dshan\portility\backend\venv\Lib\site-packages\sqlalchemy\engine\base.py", line 1986, in _exec_single_context
    self._handle_dbapi_exception(
    ~~~~~~~~~~~~~~~~~~~~~~~~~~~~^
        e, str_statement, effective_parameters, cursor, context
        ^^^^^^^^^^^^^^^^^^^^^^^^^^^^^^^^^^^^^^^^^^^^^^^^^^^^^^^
    )
    ^
  File "C:\Users\dshan\portility\backend\venv\Lib\site-packages\sqlalchemy\engine\base.py", line 2355, in _handle_dbapi_exception
    raise sqlalchemy_exception.with_traceback(exc_info[2]) from e
  File "C:\Users\dshan\portility\backend\venv\Lib\site-packages\sqlalchemy\engine\base.py", line 1967, in _exec_single_context
    self.dialect.do_execute(
    ~~~~~~~~~~~~~~~~~~~~~~~^
        cursor, str_statement, effective_parameters, context
        ^^^^^^^^^^^^^^^^^^^^^^^^^^^^^^^^^^^^^^^^^^^^^^^^^^^^
    )
    ^
  File "C:\Users\dshan\portility\backend\venv\Lib\site-packages\sqlalchemy\engine\default.py", line 951, in do_execute
    cursor.execute(statement, parameters)
    ~~~~~~~~~~~~~~^^^^^^^^^^^^^^^^^^^^^^^
sqlalchemy.exc.OperationalError: (sqlite3.OperationalError) no such table: tasks
[SQL: SELECT tasks.id AS tasks_id, tasks.title AS tasks_title, tasks.description AS tasks_description, tasks.status AS tasks_status, tasks.due_date AS tasks_due_date, tasks.created_at AS tasks_created_at, tasks.updated_at AS tasks_updated_at 
FROM tasks ORDER BY tasks.created_at DESC]
(Background on this error at: https://sqlalche.me/e/20/e3q8)
2025-10-21 22:25:04,278 [INFO] Registered tasks blueprint at /api/v1/tasks
2025-10-21 22:25:20,335 [INFO] Registered tasks blueprint at /api/v1/tasks
2025-10-21 22:25:22,036 [INFO] Registered tasks blueprint at /api/v1/tasks
2025-10-21 22:25:44,612 [INFO] GET /api/v1/tasks/ - from 127.0.0.1
2025-10-21 22:25:44,646 [ERROR] Unhandled exception: (sqlite3.OperationalError) no such table: tasks
[SQL: SELECT tasks.id AS tasks_id, tasks.title AS tasks_title, tasks.description AS tasks_description, tasks.status AS tasks_status, tasks.due_date AS tasks_due_date, tasks.created_at AS tasks_created_at, tasks.updated_at AS tasks_updated_at 
FROM tasks ORDER BY tasks.created_at DESC]
(Background on this error at: https://sqlalche.me/e/20/e3q8)
Traceback (most recent call last):
  File "C:\Users\dshan\portility\backend\venv\Lib\site-packages\sqlalchemy\engine\base.py", line 1967, in _exec_single_context
    self.dialect.do_execute(
    ~~~~~~~~~~~~~~~~~~~~~~~^
        cursor, str_statement, effective_parameters, context
        ^^^^^^^^^^^^^^^^^^^^^^^^^^^^^^^^^^^^^^^^^^^^^^^^^^^^
    )
    ^
  File "C:\Users\dshan\portility\backend\venv\Lib\site-packages\sqlalchemy\engine\default.py", line 951, in do_execute
    cursor.execute(statement, parameters)
    ~~~~~~~~~~~~~~^^^^^^^^^^^^^^^^^^^^^^^
sqlite3.OperationalError: no such table: tasks

The above exception was the direct cause of the following exception:

Traceback (most recent call last):
  File "C:\Users\dshan\portility\backend\venv\Lib\site-packages\flask\app.py", line 917, in full_dispatch_request
    rv = self.dispatch_request()
  File "C:\Users\dshan\portility\backend\venv\Lib\site-packages\flask\app.py", line 902, in dispatch_request
    return self.ensure_sync(self.view_functions[rule.endpoint])(**view_args)  # type: ignore[no-any-return]
           ~~~~~~~~~~~~~~~~~~~~~~~~~~~~~~~~~~~~~~~~~~~~~~~~~~~~^^^^^^^^^^^^^
  File "C:\Users\dshan\portility\backend\tasks\routes.py", line 12, in api_get_tasks
    all_tasks = get_tasks()
  File "C:\Users\dshan\portility\backend\tasks_store_sql.py", line 7, in get_tasks
    rows = Task.query.order_by(Task.created_at.desc()).all()
  File "C:\Users\dshan\portility\backend\venv\Lib\site-packages\sqlalchemy\orm\query.py", line 2704, in all
    return self._iter().all()  # type: ignore
           ~~~~~~~~~~^^
  File "C:\Users\dshan\portility\backend\venv\Lib\site-packages\sqlalchemy\orm\query.py", line 2857, in _iter
    result: Union[ScalarResult[_T], Result[_T]] = self.session.execute(
                                                  ~~~~~~~~~~~~~~~~~~~~^
        statement,
        ^^^^^^^^^^
        params,
        ^^^^^^^
        execution_options={"_sa_orm_load_options": self.load_options},
        ^^^^^^^^^^^^^^^^^^^^^^^^^^^^^^^^^^^^^^^^^^^^^^^^^^^^^^^^^^^^^^
    )
    ^
  File "C:\Users\dshan\portility\backend\venv\Lib\site-packages\sqlalchemy\orm\session.py", line 2351, in execute
    return self._execute_internal(
           ~~~~~~~~~~~~~~~~~~~~~~^
        statement,
        ^^^^^^^^^^
    ...<4 lines>...
        _add_event=_add_event,
        ^^^^^^^^^^^^^^^^^^^^^^
    )
    ^
  File "C:\Users\dshan\portility\backend\venv\Lib\site-packages\sqlalchemy\orm\session.py", line 2249, in _execute_internal
    result: Result[Any] = compile_state_cls.orm_execute_statement(
                          ~~~~~~~~~~~~~~~~~~~~~~~~~~~~~~~~~~~~~~~^
        self,
        ^^^^^
    ...<4 lines>...
        conn,
        ^^^^^
    )
    ^
  File "C:\Users\dshan\portility\backend\venv\Lib\site-packages\sqlalchemy\orm\context.py", line 306, in orm_execute_statement
    result = conn.execute(
        statement, params or {}, execution_options=execution_options
    )
  File "C:\Users\dshan\portility\backend\venv\Lib\site-packages\sqlalchemy\engine\base.py", line 1419, in execute
    return meth(
        self,
        distilled_parameters,
        execution_options or NO_OPTIONS,
    )
  File "C:\Users\dshan\portility\backend\venv\Lib\site-packages\sqlalchemy\sql\elements.py", line 526, in _execute_on_connection
    return connection._execute_clauseelement(
           ~~~~~~~~~~~~~~~~~~~~~~~~~~~~~~~~~^
        self, distilled_params, execution_options
        ^^^^^^^^^^^^^^^^^^^^^^^^^^^^^^^^^^^^^^^^^
    )
    ^
  File "C:\Users\dshan\portility\backend\venv\Lib\site-packages\sqlalchemy\engine\base.py", line 1641, in _execute_clauseelement
    ret = self._execute_context(
        dialect,
    ...<8 lines>...
        cache_hit=cache_hit,
    )
  File "C:\Users\dshan\portility\backend\venv\Lib\site-packages\sqlalchemy\engine\base.py", line 1846, in _execute_context
    return self._exec_single_context(
           ~~~~~~~~~~~~~~~~~~~~~~~~~^
        dialect, context, statement, parameters
        ^^^^^^^^^^^^^^^^^^^^^^^^^^^^^^^^^^^^^^^
    )
    ^
  File "C:\Users\dshan\portility\backend\venv\Lib\site-packages\sqlalchemy\engine\base.py", line 1986, in _exec_single_context
    self._handle_dbapi_exception(
    ~~~~~~~~~~~~~~~~~~~~~~~~~~~~^
        e, str_statement, effective_parameters, cursor, context
        ^^^^^^^^^^^^^^^^^^^^^^^^^^^^^^^^^^^^^^^^^^^^^^^^^^^^^^^
    )
    ^
  File "C:\Users\dshan\portility\backend\venv\Lib\site-packages\sqlalchemy\engine\base.py", line 2355, in _handle_dbapi_exception
    raise sqlalchemy_exception.with_traceback(exc_info[2]) from e
  File "C:\Users\dshan\portility\backend\venv\Lib\site-packages\sqlalchemy\engine\base.py", line 1967, in _exec_single_context
    self.dialect.do_execute(
    ~~~~~~~~~~~~~~~~~~~~~~~^
        cursor, str_statement, effective_parameters, context
        ^^^^^^^^^^^^^^^^^^^^^^^^^^^^^^^^^^^^^^^^^^^^^^^^^^^^
    )
    ^
  File "C:\Users\dshan\portility\backend\venv\Lib\site-packages\sqlalchemy\engine\default.py", line 951, in do_execute
    cursor.execute(statement, parameters)
    ~~~~~~~~~~~~~~^^^^^^^^^^^^^^^^^^^^^^^
sqlalchemy.exc.OperationalError: (sqlite3.OperationalError) no such table: tasks
[SQL: SELECT tasks.id AS tasks_id, tasks.title AS tasks_title, tasks.description AS tasks_description, tasks.status AS tasks_status, tasks.due_date AS tasks_due_date, tasks.created_at AS tasks_created_at, tasks.updated_at AS tasks_updated_at 
FROM tasks ORDER BY tasks.created_at DESC]
(Background on this error at: https://sqlalche.me/e/20/e3q8)
2025-10-21 22:25:44,726 [INFO] GET /api/v1/tasks/ - from 127.0.0.1
2025-10-21 22:25:44,730 [ERROR] Unhandled exception: (sqlite3.OperationalError) no such table: tasks
[SQL: SELECT tasks.id AS tasks_id, tasks.title AS tasks_title, tasks.description AS tasks_description, tasks.status AS tasks_status, tasks.due_date AS tasks_due_date, tasks.created_at AS tasks_created_at, tasks.updated_at AS tasks_updated_at 
FROM tasks ORDER BY tasks.created_at DESC]
(Background on this error at: https://sqlalche.me/e/20/e3q8)
Traceback (most recent call last):
  File "C:\Users\dshan\portility\backend\venv\Lib\site-packages\sqlalchemy\engine\base.py", line 1967, in _exec_single_context
    self.dialect.do_execute(
    ~~~~~~~~~~~~~~~~~~~~~~~^
        cursor, str_statement, effective_parameters, context
        ^^^^^^^^^^^^^^^^^^^^^^^^^^^^^^^^^^^^^^^^^^^^^^^^^^^^
    )
    ^
  File "C:\Users\dshan\portility\backend\venv\Lib\site-packages\sqlalchemy\engine\default.py", line 951, in do_execute
    cursor.execute(statement, parameters)
    ~~~~~~~~~~~~~~^^^^^^^^^^^^^^^^^^^^^^^
sqlite3.OperationalError: no such table: tasks

The above exception was the direct cause of the following exception:

Traceback (most recent call last):
  File "C:\Users\dshan\portility\backend\venv\Lib\site-packages\flask\app.py", line 917, in full_dispatch_request
    rv = self.dispatch_request()
  File "C:\Users\dshan\portility\backend\venv\Lib\site-packages\flask\app.py", line 902, in dispatch_request
    return self.ensure_sync(self.view_functions[rule.endpoint])(**view_args)  # type: ignore[no-any-return]
           ~~~~~~~~~~~~~~~~~~~~~~~~~~~~~~~~~~~~~~~~~~~~~~~~~~~~^^^^^^^^^^^^^
  File "C:\Users\dshan\portility\backend\tasks\routes.py", line 12, in api_get_tasks
    all_tasks = get_tasks()
  File "C:\Users\dshan\portility\backend\tasks_store_sql.py", line 7, in get_tasks
    rows = Task.query.order_by(Task.created_at.desc()).all()
  File "C:\Users\dshan\portility\backend\venv\Lib\site-packages\sqlalchemy\orm\query.py", line 2704, in all
    return self._iter().all()  # type: ignore
           ~~~~~~~~~~^^
  File "C:\Users\dshan\portility\backend\venv\Lib\site-packages\sqlalchemy\orm\query.py", line 2857, in _iter
    result: Union[ScalarResult[_T], Result[_T]] = self.session.execute(
                                                  ~~~~~~~~~~~~~~~~~~~~^
        statement,
        ^^^^^^^^^^
        params,
        ^^^^^^^
        execution_options={"_sa_orm_load_options": self.load_options},
        ^^^^^^^^^^^^^^^^^^^^^^^^^^^^^^^^^^^^^^^^^^^^^^^^^^^^^^^^^^^^^^
    )
    ^
  File "C:\Users\dshan\portility\backend\venv\Lib\site-packages\sqlalchemy\orm\session.py", line 2351, in execute
    return self._execute_internal(
           ~~~~~~~~~~~~~~~~~~~~~~^
        statement,
        ^^^^^^^^^^
    ...<4 lines>...
        _add_event=_add_event,
        ^^^^^^^^^^^^^^^^^^^^^^
    )
    ^
  File "C:\Users\dshan\portility\backend\venv\Lib\site-packages\sqlalchemy\orm\session.py", line 2249, in _execute_internal
    result: Result[Any] = compile_state_cls.orm_execute_statement(
                          ~~~~~~~~~~~~~~~~~~~~~~~~~~~~~~~~~~~~~~~^
        self,
        ^^^^^
    ...<4 lines>...
        conn,
        ^^^^^
    )
    ^
  File "C:\Users\dshan\portility\backend\venv\Lib\site-packages\sqlalchemy\orm\context.py", line 306, in orm_execute_statement
    result = conn.execute(
        statement, params or {}, execution_options=execution_options
    )
  File "C:\Users\dshan\portility\backend\venv\Lib\site-packages\sqlalchemy\engine\base.py", line 1419, in execute
    return meth(
        self,
        distilled_parameters,
        execution_options or NO_OPTIONS,
    )
  File "C:\Users\dshan\portility\backend\venv\Lib\site-packages\sqlalchemy\sql\elements.py", line 526, in _execute_on_connection
    return connection._execute_clauseelement(
           ~~~~~~~~~~~~~~~~~~~~~~~~~~~~~~~~~^
        self, distilled_params, execution_options
        ^^^^^^^^^^^^^^^^^^^^^^^^^^^^^^^^^^^^^^^^^
    )
    ^
  File "C:\Users\dshan\portility\backend\venv\Lib\site-packages\sqlalchemy\engine\base.py", line 1641, in _execute_clauseelement
    ret = self._execute_context(
        dialect,
    ...<8 lines>...
        cache_hit=cache_hit,
    )
  File "C:\Users\dshan\portility\backend\venv\Lib\site-packages\sqlalchemy\engine\base.py", line 1846, in _execute_context
    return self._exec_single_context(
           ~~~~~~~~~~~~~~~~~~~~~~~~~^
        dialect, context, statement, parameters
        ^^^^^^^^^^^^^^^^^^^^^^^^^^^^^^^^^^^^^^^
    )
    ^
  File "C:\Users\dshan\portility\backend\venv\Lib\site-packages\sqlalchemy\engine\base.py", line 1986, in _exec_single_context
    self._handle_dbapi_exception(
    ~~~~~~~~~~~~~~~~~~~~~~~~~~~~^
        e, str_statement, effective_parameters, cursor, context
        ^^^^^^^^^^^^^^^^^^^^^^^^^^^^^^^^^^^^^^^^^^^^^^^^^^^^^^^
    )
    ^
  File "C:\Users\dshan\portility\backend\venv\Lib\site-packages\sqlalchemy\engine\base.py", line 2355, in _handle_dbapi_exception
    raise sqlalchemy_exception.with_traceback(exc_info[2]) from e
  File "C:\Users\dshan\portility\backend\venv\Lib\site-packages\sqlalchemy\engine\base.py", line 1967, in _exec_single_context
    self.dialect.do_execute(
    ~~~~~~~~~~~~~~~~~~~~~~~^
        cursor, str_statement, effective_parameters, context
        ^^^^^^^^^^^^^^^^^^^^^^^^^^^^^^^^^^^^^^^^^^^^^^^^^^^^
    )
    ^
  File "C:\Users\dshan\portility\backend\venv\Lib\site-packages\sqlalchemy\engine\default.py", line 951, in do_execute
    cursor.execute(statement, parameters)
    ~~~~~~~~~~~~~~^^^^^^^^^^^^^^^^^^^^^^^
sqlalchemy.exc.OperationalError: (sqlite3.OperationalError) no such table: tasks
[SQL: SELECT tasks.id AS tasks_id, tasks.title AS tasks_title, tasks.description AS tasks_description, tasks.status AS tasks_status, tasks.due_date AS tasks_due_date, tasks.created_at AS tasks_created_at, tasks.updated_at AS tasks_updated_at 
FROM tasks ORDER BY tasks.created_at DESC]
(Background on this error at: https://sqlalche.me/e/20/e3q8)
2025-10-21 22:26:34,922 [INFO] GET /api/v1/tasks - from 127.0.0.1
2025-10-21 22:26:35,031 [INFO] GET /api/v1/tasks/ - from 127.0.0.1
2025-10-21 22:26:35,062 [ERROR] Unhandled exception: (sqlite3.OperationalError) no such table: tasks
[SQL: SELECT tasks.id AS tasks_id, tasks.title AS tasks_title, tasks.description AS tasks_description, tasks.status AS tasks_status, tasks.due_date AS tasks_due_date, tasks.created_at AS tasks_created_at, tasks.updated_at AS tasks_updated_at 
FROM tasks ORDER BY tasks.created_at DESC]
(Background on this error at: https://sqlalche.me/e/20/e3q8)
Traceback (most recent call last):
  File "C:\Users\dshan\portility\backend\venv\Lib\site-packages\sqlalchemy\engine\base.py", line 1967, in _exec_single_context
    self.dialect.do_execute(
    ~~~~~~~~~~~~~~~~~~~~~~~^
        cursor, str_statement, effective_parameters, context
        ^^^^^^^^^^^^^^^^^^^^^^^^^^^^^^^^^^^^^^^^^^^^^^^^^^^^
    )
    ^
  File "C:\Users\dshan\portility\backend\venv\Lib\site-packages\sqlalchemy\engine\default.py", line 951, in do_execute
    cursor.execute(statement, parameters)
    ~~~~~~~~~~~~~~^^^^^^^^^^^^^^^^^^^^^^^
sqlite3.OperationalError: no such table: tasks

The above exception was the direct cause of the following exception:

Traceback (most recent call last):
  File "C:\Users\dshan\portility\backend\venv\Lib\site-packages\flask\app.py", line 917, in full_dispatch_request
    rv = self.dispatch_request()
  File "C:\Users\dshan\portility\backend\venv\Lib\site-packages\flask\app.py", line 902, in dispatch_request
    return self.ensure_sync(self.view_functions[rule.endpoint])(**view_args)  # type: ignore[no-any-return]
           ~~~~~~~~~~~~~~~~~~~~~~~~~~~~~~~~~~~~~~~~~~~~~~~~~~~~^^^^^^^^^^^^^
  File "C:\Users\dshan\portility\backend\tasks\routes.py", line 12, in api_get_tasks
    all_tasks = get_tasks()
  File "C:\Users\dshan\portility\backend\tasks_store_sql.py", line 7, in get_tasks
    rows = Task.query.order_by(Task.created_at.desc()).all()
  File "C:\Users\dshan\portility\backend\venv\Lib\site-packages\sqlalchemy\orm\query.py", line 2704, in all
    return self._iter().all()  # type: ignore
           ~~~~~~~~~~^^
  File "C:\Users\dshan\portility\backend\venv\Lib\site-packages\sqlalchemy\orm\query.py", line 2857, in _iter
    result: Union[ScalarResult[_T], Result[_T]] = self.session.execute(
                                                  ~~~~~~~~~~~~~~~~~~~~^
        statement,
        ^^^^^^^^^^
        params,
        ^^^^^^^
        execution_options={"_sa_orm_load_options": self.load_options},
        ^^^^^^^^^^^^^^^^^^^^^^^^^^^^^^^^^^^^^^^^^^^^^^^^^^^^^^^^^^^^^^
    )
    ^
  File "C:\Users\dshan\portility\backend\venv\Lib\site-packages\sqlalchemy\orm\session.py", line 2351, in execute
    return self._execute_internal(
           ~~~~~~~~~~~~~~~~~~~~~~^
        statement,
        ^^^^^^^^^^
    ...<4 lines>...
        _add_event=_add_event,
        ^^^^^^^^^^^^^^^^^^^^^^
    )
    ^
  File "C:\Users\dshan\portility\backend\venv\Lib\site-packages\sqlalchemy\orm\session.py", line 2249, in _execute_internal
    result: Result[Any] = compile_state_cls.orm_execute_statement(
                          ~~~~~~~~~~~~~~~~~~~~~~~~~~~~~~~~~~~~~~~^
        self,
        ^^^^^
    ...<4 lines>...
        conn,
        ^^^^^
    )
    ^
  File "C:\Users\dshan\portility\backend\venv\Lib\site-packages\sqlalchemy\orm\context.py", line 306, in orm_execute_statement
    result = conn.execute(
        statement, params or {}, execution_options=execution_options
    )
  File "C:\Users\dshan\portility\backend\venv\Lib\site-packages\sqlalchemy\engine\base.py", line 1419, in execute
    return meth(
        self,
        distilled_parameters,
        execution_options or NO_OPTIONS,
    )
  File "C:\Users\dshan\portility\backend\venv\Lib\site-packages\sqlalchemy\sql\elements.py", line 526, in _execute_on_connection
    return connection._execute_clauseelement(
           ~~~~~~~~~~~~~~~~~~~~~~~~~~~~~~~~~^
        self, distilled_params, execution_options
        ^^^^^^^^^^^^^^^^^^^^^^^^^^^^^^^^^^^^^^^^^
    )
    ^
  File "C:\Users\dshan\portility\backend\venv\Lib\site-packages\sqlalchemy\engine\base.py", line 1641, in _execute_clauseelement
    ret = self._execute_context(
        dialect,
    ...<8 lines>...
        cache_hit=cache_hit,
    )
  File "C:\Users\dshan\portility\backend\venv\Lib\site-packages\sqlalchemy\engine\base.py", line 1846, in _execute_context
    return self._exec_single_context(
           ~~~~~~~~~~~~~~~~~~~~~~~~~^
        dialect, context, statement, parameters
        ^^^^^^^^^^^^^^^^^^^^^^^^^^^^^^^^^^^^^^^
    )
    ^
  File "C:\Users\dshan\portility\backend\venv\Lib\site-packages\sqlalchemy\engine\base.py", line 1986, in _exec_single_context
    self._handle_dbapi_exception(
    ~~~~~~~~~~~~~~~~~~~~~~~~~~~~^
        e, str_statement, effective_parameters, cursor, context
        ^^^^^^^^^^^^^^^^^^^^^^^^^^^^^^^^^^^^^^^^^^^^^^^^^^^^^^^
    )
    ^
  File "C:\Users\dshan\portility\backend\venv\Lib\site-packages\sqlalchemy\engine\base.py", line 2355, in _handle_dbapi_exception
    raise sqlalchemy_exception.with_traceback(exc_info[2]) from e
  File "C:\Users\dshan\portility\backend\venv\Lib\site-packages\sqlalchemy\engine\base.py", line 1967, in _exec_single_context
    self.dialect.do_execute(
    ~~~~~~~~~~~~~~~~~~~~~~~^
        cursor, str_statement, effective_parameters, context
        ^^^^^^^^^^^^^^^^^^^^^^^^^^^^^^^^^^^^^^^^^^^^^^^^^^^^
    )
    ^
  File "C:\Users\dshan\portility\backend\venv\Lib\site-packages\sqlalchemy\engine\default.py", line 951, in do_execute
    cursor.execute(statement, parameters)
    ~~~~~~~~~~~~~~^^^^^^^^^^^^^^^^^^^^^^^
sqlalchemy.exc.OperationalError: (sqlite3.OperationalError) no such table: tasks
[SQL: SELECT tasks.id AS tasks_id, tasks.title AS tasks_title, tasks.description AS tasks_description, tasks.status AS tasks_status, tasks.due_date AS tasks_due_date, tasks.created_at AS tasks_created_at, tasks.updated_at AS tasks_updated_at 
FROM tasks ORDER BY tasks.created_at DESC]
(Background on this error at: https://sqlalche.me/e/20/e3q8)
2025-10-22 11:11:21,212 [INFO] Registered tasks blueprint at /api/v1/tasks
2025-10-22 11:11:58,069 [INFO] Registered tasks blueprint at /api/v1/tasks
2025-10-22 11:13:07,550 [INFO] GET /api/v1/tasks/ - from 127.0.0.1
2025-10-22 11:13:07,597 [ERROR] Unhandled exception: (sqlite3.OperationalError) no such table: tasks
[SQL: SELECT tasks.id AS tasks_id, tasks.title AS tasks_title, tasks.description AS tasks_description, tasks.status AS tasks_status, tasks.due_date AS tasks_due_date, tasks.created_at AS tasks_created_at, tasks.updated_at AS tasks_updated_at 
FROM tasks ORDER BY tasks.created_at DESC]
(Background on this error at: https://sqlalche.me/e/20/e3q8)
Traceback (most recent call last):
  File "C:\Users\dshan\portility\backend\venv\Lib\site-packages\sqlalchemy\engine\base.py", line 1967, in _exec_single_context
    self.dialect.do_execute(
    ~~~~~~~~~~~~~~~~~~~~~~~^
        cursor, str_statement, effective_parameters, context
        ^^^^^^^^^^^^^^^^^^^^^^^^^^^^^^^^^^^^^^^^^^^^^^^^^^^^
    )
    ^
  File "C:\Users\dshan\portility\backend\venv\Lib\site-packages\sqlalchemy\engine\default.py", line 951, in do_execute
    cursor.execute(statement, parameters)
    ~~~~~~~~~~~~~~^^^^^^^^^^^^^^^^^^^^^^^
sqlite3.OperationalError: no such table: tasks

The above exception was the direct cause of the following exception:

Traceback (most recent call last):
  File "C:\Users\dshan\portility\backend\venv\Lib\site-packages\flask\app.py", line 917, in full_dispatch_request
    rv = self.dispatch_request()
  File "C:\Users\dshan\portility\backend\venv\Lib\site-packages\flask\app.py", line 902, in dispatch_request
    return self.ensure_sync(self.view_functions[rule.endpoint])(**view_args)  # type: ignore[no-any-return]
           ~~~~~~~~~~~~~~~~~~~~~~~~~~~~~~~~~~~~~~~~~~~~~~~~~~~~^^^^^^^^^^^^^
  File "C:\Users\dshan\portility\backend\tasks\routes.py", line 12, in api_get_tasks
    all_tasks = get_tasks()
  File "C:\Users\dshan\portility\backend\tasks_store_sql.py", line 6, in get_tasks
    rows = Task.query.order_by(Task.created_at.desc()).all()
  File "C:\Users\dshan\portility\backend\venv\Lib\site-packages\sqlalchemy\orm\query.py", line 2704, in all
    return self._iter().all()  # type: ignore
           ~~~~~~~~~~^^
  File "C:\Users\dshan\portility\backend\venv\Lib\site-packages\sqlalchemy\orm\query.py", line 2857, in _iter
    result: Union[ScalarResult[_T], Result[_T]] = self.session.execute(
                                                  ~~~~~~~~~~~~~~~~~~~~^
        statement,
        ^^^^^^^^^^
        params,
        ^^^^^^^
        execution_options={"_sa_orm_load_options": self.load_options},
        ^^^^^^^^^^^^^^^^^^^^^^^^^^^^^^^^^^^^^^^^^^^^^^^^^^^^^^^^^^^^^^
    )
    ^
  File "C:\Users\dshan\portility\backend\venv\Lib\site-packages\sqlalchemy\orm\session.py", line 2351, in execute
    return self._execute_internal(
           ~~~~~~~~~~~~~~~~~~~~~~^
        statement,
        ^^^^^^^^^^
    ...<4 lines>...
        _add_event=_add_event,
        ^^^^^^^^^^^^^^^^^^^^^^
    )
    ^
  File "C:\Users\dshan\portility\backend\venv\Lib\site-packages\sqlalchemy\orm\session.py", line 2249, in _execute_internal
    result: Result[Any] = compile_state_cls.orm_execute_statement(
                          ~~~~~~~~~~~~~~~~~~~~~~~~~~~~~~~~~~~~~~~^
        self,
        ^^^^^
    ...<4 lines>...
        conn,
        ^^^^^
    )
    ^
  File "C:\Users\dshan\portility\backend\venv\Lib\site-packages\sqlalchemy\orm\context.py", line 306, in orm_execute_statement
    result = conn.execute(
        statement, params or {}, execution_options=execution_options
    )
  File "C:\Users\dshan\portility\backend\venv\Lib\site-packages\sqlalchemy\engine\base.py", line 1419, in execute
    return meth(
        self,
        distilled_parameters,
        execution_options or NO_OPTIONS,
    )
  File "C:\Users\dshan\portility\backend\venv\Lib\site-packages\sqlalchemy\sql\elements.py", line 526, in _execute_on_connection
    return connection._execute_clauseelement(
           ~~~~~~~~~~~~~~~~~~~~~~~~~~~~~~~~~^
        self, distilled_params, execution_options
        ^^^^^^^^^^^^^^^^^^^^^^^^^^^^^^^^^^^^^^^^^
    )
    ^
  File "C:\Users\dshan\portility\backend\venv\Lib\site-packages\sqlalchemy\engine\base.py", line 1641, in _execute_clauseelement
    ret = self._execute_context(
        dialect,
    ...<8 lines>...
        cache_hit=cache_hit,
    )
  File "C:\Users\dshan\portility\backend\venv\Lib\site-packages\sqlalchemy\engine\base.py", line 1846, in _execute_context
    return self._exec_single_context(
           ~~~~~~~~~~~~~~~~~~~~~~~~~^
        dialect, context, statement, parameters
        ^^^^^^^^^^^^^^^^^^^^^^^^^^^^^^^^^^^^^^^
    )
    ^
  File "C:\Users\dshan\portility\backend\venv\Lib\site-packages\sqlalchemy\engine\base.py", line 1986, in _exec_single_context
    self._handle_dbapi_exception(
    ~~~~~~~~~~~~~~~~~~~~~~~~~~~~^
        e, str_statement, effective_parameters, cursor, context
        ^^^^^^^^^^^^^^^^^^^^^^^^^^^^^^^^^^^^^^^^^^^^^^^^^^^^^^^
    )
    ^
  File "C:\Users\dshan\portility\backend\venv\Lib\site-packages\sqlalchemy\engine\base.py", line 2355, in _handle_dbapi_exception
    raise sqlalchemy_exception.with_traceback(exc_info[2]) from e
  File "C:\Users\dshan\portility\backend\venv\Lib\site-packages\sqlalchemy\engine\base.py", line 1967, in _exec_single_context
    self.dialect.do_execute(
    ~~~~~~~~~~~~~~~~~~~~~~~^
        cursor, str_statement, effective_parameters, context
        ^^^^^^^^^^^^^^^^^^^^^^^^^^^^^^^^^^^^^^^^^^^^^^^^^^^^
    )
    ^
  File "C:\Users\dshan\portility\backend\venv\Lib\site-packages\sqlalchemy\engine\default.py", line 951, in do_execute
    cursor.execute(statement, parameters)
    ~~~~~~~~~~~~~~^^^^^^^^^^^^^^^^^^^^^^^
sqlalchemy.exc.OperationalError: (sqlite3.OperationalError) no such table: tasks
[SQL: SELECT tasks.id AS tasks_id, tasks.title AS tasks_title, tasks.description AS tasks_description, tasks.status AS tasks_status, tasks.due_date AS tasks_due_date, tasks.created_at AS tasks_created_at, tasks.updated_at AS tasks_updated_at 
FROM tasks ORDER BY tasks.created_at DESC]
(Background on this error at: https://sqlalche.me/e/20/e3q8)
2025-10-22 11:13:08,039 [INFO] GET /api/v1/tasks/ - from 127.0.0.1
2025-10-22 11:13:08,042 [ERROR] Unhandled exception: (sqlite3.OperationalError) no such table: tasks
[SQL: SELECT tasks.id AS tasks_id, tasks.title AS tasks_title, tasks.description AS tasks_description, tasks.status AS tasks_status, tasks.due_date AS tasks_due_date, tasks.created_at AS tasks_created_at, tasks.updated_at AS tasks_updated_at 
FROM tasks ORDER BY tasks.created_at DESC]
(Background on this error at: https://sqlalche.me/e/20/e3q8)
Traceback (most recent call last):
  File "C:\Users\dshan\portility\backend\venv\Lib\site-packages\sqlalchemy\engine\base.py", line 1967, in _exec_single_context
    self.dialect.do_execute(
    ~~~~~~~~~~~~~~~~~~~~~~~^
        cursor, str_statement, effective_parameters, context
        ^^^^^^^^^^^^^^^^^^^^^^^^^^^^^^^^^^^^^^^^^^^^^^^^^^^^
    )
    ^
  File "C:\Users\dshan\portility\backend\venv\Lib\site-packages\sqlalchemy\engine\default.py", line 951, in do_execute
    cursor.execute(statement, parameters)
    ~~~~~~~~~~~~~~^^^^^^^^^^^^^^^^^^^^^^^
sqlite3.OperationalError: no such table: tasks

The above exception was the direct cause of the following exception:

Traceback (most recent call last):
  File "C:\Users\dshan\portility\backend\venv\Lib\site-packages\flask\app.py", line 917, in full_dispatch_request
    rv = self.dispatch_request()
  File "C:\Users\dshan\portility\backend\venv\Lib\site-packages\flask\app.py", line 902, in dispatch_request
    return self.ensure_sync(self.view_functions[rule.endpoint])(**view_args)  # type: ignore[no-any-return]
           ~~~~~~~~~~~~~~~~~~~~~~~~~~~~~~~~~~~~~~~~~~~~~~~~~~~~^^^^^^^^^^^^^
  File "C:\Users\dshan\portility\backend\tasks\routes.py", line 12, in api_get_tasks
    all_tasks = get_tasks()
  File "C:\Users\dshan\portility\backend\tasks_store_sql.py", line 6, in get_tasks
    rows = Task.query.order_by(Task.created_at.desc()).all()
  File "C:\Users\dshan\portility\backend\venv\Lib\site-packages\sqlalchemy\orm\query.py", line 2704, in all
    return self._iter().all()  # type: ignore
           ~~~~~~~~~~^^
  File "C:\Users\dshan\portility\backend\venv\Lib\site-packages\sqlalchemy\orm\query.py", line 2857, in _iter
    result: Union[ScalarResult[_T], Result[_T]] = self.session.execute(
                                                  ~~~~~~~~~~~~~~~~~~~~^
        statement,
        ^^^^^^^^^^
        params,
        ^^^^^^^
        execution_options={"_sa_orm_load_options": self.load_options},
        ^^^^^^^^^^^^^^^^^^^^^^^^^^^^^^^^^^^^^^^^^^^^^^^^^^^^^^^^^^^^^^
    )
    ^
  File "C:\Users\dshan\portility\backend\venv\Lib\site-packages\sqlalchemy\orm\session.py", line 2351, in execute
    return self._execute_internal(
           ~~~~~~~~~~~~~~~~~~~~~~^
        statement,
        ^^^^^^^^^^
    ...<4 lines>...
        _add_event=_add_event,
        ^^^^^^^^^^^^^^^^^^^^^^
    )
    ^
  File "C:\Users\dshan\portility\backend\venv\Lib\site-packages\sqlalchemy\orm\session.py", line 2249, in _execute_internal
    result: Result[Any] = compile_state_cls.orm_execute_statement(
                          ~~~~~~~~~~~~~~~~~~~~~~~~~~~~~~~~~~~~~~~^
        self,
        ^^^^^
    ...<4 lines>...
        conn,
        ^^^^^
    )
    ^
  File "C:\Users\dshan\portility\backend\venv\Lib\site-packages\sqlalchemy\orm\context.py", line 306, in orm_execute_statement
    result = conn.execute(
        statement, params or {}, execution_options=execution_options
    )
  File "C:\Users\dshan\portility\backend\venv\Lib\site-packages\sqlalchemy\engine\base.py", line 1419, in execute
    return meth(
        self,
        distilled_parameters,
        execution_options or NO_OPTIONS,
    )
  File "C:\Users\dshan\portility\backend\venv\Lib\site-packages\sqlalchemy\sql\elements.py", line 526, in _execute_on_connection
    return connection._execute_clauseelement(
           ~~~~~~~~~~~~~~~~~~~~~~~~~~~~~~~~~^
        self, distilled_params, execution_options
        ^^^^^^^^^^^^^^^^^^^^^^^^^^^^^^^^^^^^^^^^^
    )
    ^
  File "C:\Users\dshan\portility\backend\venv\Lib\site-packages\sqlalchemy\engine\base.py", line 1641, in _execute_clauseelement
    ret = self._execute_context(
        dialect,
    ...<8 lines>...
        cache_hit=cache_hit,
    )
  File "C:\Users\dshan\portility\backend\venv\Lib\site-packages\sqlalchemy\engine\base.py", line 1846, in _execute_context
    return self._exec_single_context(
           ~~~~~~~~~~~~~~~~~~~~~~~~~^
        dialect, context, statement, parameters
        ^^^^^^^^^^^^^^^^^^^^^^^^^^^^^^^^^^^^^^^
    )
    ^
  File "C:\Users\dshan\portility\backend\venv\Lib\site-packages\sqlalchemy\engine\base.py", line 1986, in _exec_single_context
    self._handle_dbapi_exception(
    ~~~~~~~~~~~~~~~~~~~~~~~~~~~~^
        e, str_statement, effective_parameters, cursor, context
        ^^^^^^^^^^^^^^^^^^^^^^^^^^^^^^^^^^^^^^^^^^^^^^^^^^^^^^^
    )
    ^
  File "C:\Users\dshan\portility\backend\venv\Lib\site-packages\sqlalchemy\engine\base.py", line 2355, in _handle_dbapi_exception
    raise sqlalchemy_exception.with_traceback(exc_info[2]) from e
  File "C:\Users\dshan\portility\backend\venv\Lib\site-packages\sqlalchemy\engine\base.py", line 1967, in _exec_single_context
    self.dialect.do_execute(
    ~~~~~~~~~~~~~~~~~~~~~~~^
        cursor, str_statement, effective_parameters, context
        ^^^^^^^^^^^^^^^^^^^^^^^^^^^^^^^^^^^^^^^^^^^^^^^^^^^^
    )
    ^
  File "C:\Users\dshan\portility\backend\venv\Lib\site-packages\sqlalchemy\engine\default.py", line 951, in do_execute
    cursor.execute(statement, parameters)
    ~~~~~~~~~~~~~~^^^^^^^^^^^^^^^^^^^^^^^
sqlalchemy.exc.OperationalError: (sqlite3.OperationalError) no such table: tasks
[SQL: SELECT tasks.id AS tasks_id, tasks.title AS tasks_title, tasks.description AS tasks_description, tasks.status AS tasks_status, tasks.due_date AS tasks_due_date, tasks.created_at AS tasks_created_at, tasks.updated_at AS tasks_updated_at 
FROM tasks ORDER BY tasks.created_at DESC]
(Background on this error at: https://sqlalche.me/e/20/e3q8)
2025-10-22 11:13:46,900 [INFO] Registered tasks blueprint at /api/v1/tasks
2025-10-22 11:13:49,785 [INFO] Registered tasks blueprint at /api/v1/tasks
2025-10-22 11:13:59,675 [INFO] GET /api/v1/tasks/ - from 127.0.0.1
2025-10-22 11:13:59,703 [ERROR] Unhandled exception: (sqlite3.OperationalError) no such table: tasks
[SQL: SELECT tasks.id AS tasks_id, tasks.title AS tasks_title, tasks.description AS tasks_description, tasks.status AS tasks_status, tasks.due_date AS tasks_due_date, tasks.created_at AS tasks_created_at, tasks.updated_at AS tasks_updated_at 
FROM tasks ORDER BY tasks.created_at DESC]
(Background on this error at: https://sqlalche.me/e/20/e3q8)
Traceback (most recent call last):
  File "C:\Users\dshan\portility\backend\venv\Lib\site-packages\sqlalchemy\engine\base.py", line 1967, in _exec_single_context
    self.dialect.do_execute(
    ~~~~~~~~~~~~~~~~~~~~~~~^
        cursor, str_statement, effective_parameters, context
        ^^^^^^^^^^^^^^^^^^^^^^^^^^^^^^^^^^^^^^^^^^^^^^^^^^^^
    )
    ^
  File "C:\Users\dshan\portility\backend\venv\Lib\site-packages\sqlalchemy\engine\default.py", line 951, in do_execute
    cursor.execute(statement, parameters)
    ~~~~~~~~~~~~~~^^^^^^^^^^^^^^^^^^^^^^^
sqlite3.OperationalError: no such table: tasks

The above exception was the direct cause of the following exception:

Traceback (most recent call last):
  File "C:\Users\dshan\portility\backend\venv\Lib\site-packages\flask\app.py", line 917, in full_dispatch_request
    rv = self.dispatch_request()
  File "C:\Users\dshan\portility\backend\venv\Lib\site-packages\flask\app.py", line 902, in dispatch_request
    return self.ensure_sync(self.view_functions[rule.endpoint])(**view_args)  # type: ignore[no-any-return]
           ~~~~~~~~~~~~~~~~~~~~~~~~~~~~~~~~~~~~~~~~~~~~~~~~~~~~^^^^^^^^^^^^^
  File "C:\Users\dshan\portility\backend\tasks\routes.py", line 12, in api_get_tasks
    all_tasks = get_tasks()
  File "C:\Users\dshan\portility\backend\tasks_store_sql.py", line 6, in get_tasks
    rows = Task.query.order_by(Task.created_at.desc()).all()
  File "C:\Users\dshan\portility\backend\venv\Lib\site-packages\sqlalchemy\orm\query.py", line 2704, in all
    return self._iter().all()  # type: ignore
           ~~~~~~~~~~^^
  File "C:\Users\dshan\portility\backend\venv\Lib\site-packages\sqlalchemy\orm\query.py", line 2857, in _iter
    result: Union[ScalarResult[_T], Result[_T]] = self.session.execute(
                                                  ~~~~~~~~~~~~~~~~~~~~^
        statement,
        ^^^^^^^^^^
        params,
        ^^^^^^^
        execution_options={"_sa_orm_load_options": self.load_options},
        ^^^^^^^^^^^^^^^^^^^^^^^^^^^^^^^^^^^^^^^^^^^^^^^^^^^^^^^^^^^^^^
    )
    ^
  File "C:\Users\dshan\portility\backend\venv\Lib\site-packages\sqlalchemy\orm\session.py", line 2351, in execute
    return self._execute_internal(
           ~~~~~~~~~~~~~~~~~~~~~~^
        statement,
        ^^^^^^^^^^
    ...<4 lines>...
        _add_event=_add_event,
        ^^^^^^^^^^^^^^^^^^^^^^
    )
    ^
  File "C:\Users\dshan\portility\backend\venv\Lib\site-packages\sqlalchemy\orm\session.py", line 2249, in _execute_internal
    result: Result[Any] = compile_state_cls.orm_execute_statement(
                          ~~~~~~~~~~~~~~~~~~~~~~~~~~~~~~~~~~~~~~~^
        self,
        ^^^^^
    ...<4 lines>...
        conn,
        ^^^^^
    )
    ^
  File "C:\Users\dshan\portility\backend\venv\Lib\site-packages\sqlalchemy\orm\context.py", line 306, in orm_execute_statement
    result = conn.execute(
        statement, params or {}, execution_options=execution_options
    )
  File "C:\Users\dshan\portility\backend\venv\Lib\site-packages\sqlalchemy\engine\base.py", line 1419, in execute
    return meth(
        self,
        distilled_parameters,
        execution_options or NO_OPTIONS,
    )
  File "C:\Users\dshan\portility\backend\venv\Lib\site-packages\sqlalchemy\sql\elements.py", line 526, in _execute_on_connection
    return connection._execute_clauseelement(
           ~~~~~~~~~~~~~~~~~~~~~~~~~~~~~~~~~^
        self, distilled_params, execution_options
        ^^^^^^^^^^^^^^^^^^^^^^^^^^^^^^^^^^^^^^^^^
    )
    ^
  File "C:\Users\dshan\portility\backend\venv\Lib\site-packages\sqlalchemy\engine\base.py", line 1641, in _execute_clauseelement
    ret = self._execute_context(
        dialect,
    ...<8 lines>...
        cache_hit=cache_hit,
    )
  File "C:\Users\dshan\portility\backend\venv\Lib\site-packages\sqlalchemy\engine\base.py", line 1846, in _execute_context
    return self._exec_single_context(
           ~~~~~~~~~~~~~~~~~~~~~~~~~^
        dialect, context, statement, parameters
        ^^^^^^^^^^^^^^^^^^^^^^^^^^^^^^^^^^^^^^^
    )
    ^
  File "C:\Users\dshan\portility\backend\venv\Lib\site-packages\sqlalchemy\engine\base.py", line 1986, in _exec_single_context
    self._handle_dbapi_exception(
    ~~~~~~~~~~~~~~~~~~~~~~~~~~~~^
        e, str_statement, effective_parameters, cursor, context
        ^^^^^^^^^^^^^^^^^^^^^^^^^^^^^^^^^^^^^^^^^^^^^^^^^^^^^^^
    )
    ^
  File "C:\Users\dshan\portility\backend\venv\Lib\site-packages\sqlalchemy\engine\base.py", line 2355, in _handle_dbapi_exception
    raise sqlalchemy_exception.with_traceback(exc_info[2]) from e
  File "C:\Users\dshan\portility\backend\venv\Lib\site-packages\sqlalchemy\engine\base.py", line 1967, in _exec_single_context
    self.dialect.do_execute(
    ~~~~~~~~~~~~~~~~~~~~~~~^
        cursor, str_statement, effective_parameters, context
        ^^^^^^^^^^^^^^^^^^^^^^^^^^^^^^^^^^^^^^^^^^^^^^^^^^^^
    )
    ^
  File "C:\Users\dshan\portility\backend\venv\Lib\site-packages\sqlalchemy\engine\default.py", line 951, in do_execute
    cursor.execute(statement, parameters)
    ~~~~~~~~~~~~~~^^^^^^^^^^^^^^^^^^^^^^^
sqlalchemy.exc.OperationalError: (sqlite3.OperationalError) no such table: tasks
[SQL: SELECT tasks.id AS tasks_id, tasks.title AS tasks_title, tasks.description AS tasks_description, tasks.status AS tasks_status, tasks.due_date AS tasks_due_date, tasks.created_at AS tasks_created_at, tasks.updated_at AS tasks_updated_at 
FROM tasks ORDER BY tasks.created_at DESC]
(Background on this error at: https://sqlalche.me/e/20/e3q8)
2025-10-22 11:13:59,756 [INFO] GET /api/v1/tasks/ - from 127.0.0.1
2025-10-22 11:13:59,761 [ERROR] Unhandled exception: (sqlite3.OperationalError) no such table: tasks
[SQL: SELECT tasks.id AS tasks_id, tasks.title AS tasks_title, tasks.description AS tasks_description, tasks.status AS tasks_status, tasks.due_date AS tasks_due_date, tasks.created_at AS tasks_created_at, tasks.updated_at AS tasks_updated_at 
FROM tasks ORDER BY tasks.created_at DESC]
(Background on this error at: https://sqlalche.me/e/20/e3q8)
Traceback (most recent call last):
  File "C:\Users\dshan\portility\backend\venv\Lib\site-packages\sqlalchemy\engine\base.py", line 1967, in _exec_single_context
    self.dialect.do_execute(
    ~~~~~~~~~~~~~~~~~~~~~~~^
        cursor, str_statement, effective_parameters, context
        ^^^^^^^^^^^^^^^^^^^^^^^^^^^^^^^^^^^^^^^^^^^^^^^^^^^^
    )
    ^
  File "C:\Users\dshan\portility\backend\venv\Lib\site-packages\sqlalchemy\engine\default.py", line 951, in do_execute
    cursor.execute(statement, parameters)
    ~~~~~~~~~~~~~~^^^^^^^^^^^^^^^^^^^^^^^
sqlite3.OperationalError: no such table: tasks

The above exception was the direct cause of the following exception:

Traceback (most recent call last):
  File "C:\Users\dshan\portility\backend\venv\Lib\site-packages\flask\app.py", line 917, in full_dispatch_request
    rv = self.dispatch_request()
  File "C:\Users\dshan\portility\backend\venv\Lib\site-packages\flask\app.py", line 902, in dispatch_request
    return self.ensure_sync(self.view_functions[rule.endpoint])(**view_args)  # type: ignore[no-any-return]
           ~~~~~~~~~~~~~~~~~~~~~~~~~~~~~~~~~~~~~~~~~~~~~~~~~~~~^^^^^^^^^^^^^
  File "C:\Users\dshan\portility\backend\tasks\routes.py", line 12, in api_get_tasks
    all_tasks = get_tasks()
  File "C:\Users\dshan\portility\backend\tasks_store_sql.py", line 6, in get_tasks
    rows = Task.query.order_by(Task.created_at.desc()).all()
  File "C:\Users\dshan\portility\backend\venv\Lib\site-packages\sqlalchemy\orm\query.py", line 2704, in all
    return self._iter().all()  # type: ignore
           ~~~~~~~~~~^^
  File "C:\Users\dshan\portility\backend\venv\Lib\site-packages\sqlalchemy\orm\query.py", line 2857, in _iter
    result: Union[ScalarResult[_T], Result[_T]] = self.session.execute(
                                                  ~~~~~~~~~~~~~~~~~~~~^
        statement,
        ^^^^^^^^^^
        params,
        ^^^^^^^
        execution_options={"_sa_orm_load_options": self.load_options},
        ^^^^^^^^^^^^^^^^^^^^^^^^^^^^^^^^^^^^^^^^^^^^^^^^^^^^^^^^^^^^^^
    )
    ^
  File "C:\Users\dshan\portility\backend\venv\Lib\site-packages\sqlalchemy\orm\session.py", line 2351, in execute
    return self._execute_internal(
           ~~~~~~~~~~~~~~~~~~~~~~^
        statement,
        ^^^^^^^^^^
    ...<4 lines>...
        _add_event=_add_event,
        ^^^^^^^^^^^^^^^^^^^^^^
    )
    ^
  File "C:\Users\dshan\portility\backend\venv\Lib\site-packages\sqlalchemy\orm\session.py", line 2249, in _execute_internal
    result: Result[Any] = compile_state_cls.orm_execute_statement(
                          ~~~~~~~~~~~~~~~~~~~~~~~~~~~~~~~~~~~~~~~^
        self,
        ^^^^^
    ...<4 lines>...
        conn,
        ^^^^^
    )
    ^
  File "C:\Users\dshan\portility\backend\venv\Lib\site-packages\sqlalchemy\orm\context.py", line 306, in orm_execute_statement
    result = conn.execute(
        statement, params or {}, execution_options=execution_options
    )
  File "C:\Users\dshan\portility\backend\venv\Lib\site-packages\sqlalchemy\engine\base.py", line 1419, in execute
    return meth(
        self,
        distilled_parameters,
        execution_options or NO_OPTIONS,
    )
  File "C:\Users\dshan\portility\backend\venv\Lib\site-packages\sqlalchemy\sql\elements.py", line 526, in _execute_on_connection
    return connection._execute_clauseelement(
           ~~~~~~~~~~~~~~~~~~~~~~~~~~~~~~~~~^
        self, distilled_params, execution_options
        ^^^^^^^^^^^^^^^^^^^^^^^^^^^^^^^^^^^^^^^^^
    )
    ^
  File "C:\Users\dshan\portility\backend\venv\Lib\site-packages\sqlalchemy\engine\base.py", line 1641, in _execute_clauseelement
    ret = self._execute_context(
        dialect,
    ...<8 lines>...
        cache_hit=cache_hit,
    )
  File "C:\Users\dshan\portility\backend\venv\Lib\site-packages\sqlalchemy\engine\base.py", line 1846, in _execute_context
    return self._exec_single_context(
           ~~~~~~~~~~~~~~~~~~~~~~~~~^
        dialect, context, statement, parameters
        ^^^^^^^^^^^^^^^^^^^^^^^^^^^^^^^^^^^^^^^
    )
    ^
  File "C:\Users\dshan\portility\backend\venv\Lib\site-packages\sqlalchemy\engine\base.py", line 1986, in _exec_single_context
    self._handle_dbapi_exception(
    ~~~~~~~~~~~~~~~~~~~~~~~~~~~~^
        e, str_statement, effective_parameters, cursor, context
        ^^^^^^^^^^^^^^^^^^^^^^^^^^^^^^^^^^^^^^^^^^^^^^^^^^^^^^^
    )
    ^
  File "C:\Users\dshan\portility\backend\venv\Lib\site-packages\sqlalchemy\engine\base.py", line 2355, in _handle_dbapi_exception
    raise sqlalchemy_exception.with_traceback(exc_info[2]) from e
  File "C:\Users\dshan\portility\backend\venv\Lib\site-packages\sqlalchemy\engine\base.py", line 1967, in _exec_single_context
    self.dialect.do_execute(
    ~~~~~~~~~~~~~~~~~~~~~~~^
        cursor, str_statement, effective_parameters, context
        ^^^^^^^^^^^^^^^^^^^^^^^^^^^^^^^^^^^^^^^^^^^^^^^^^^^^
    )
    ^
  File "C:\Users\dshan\portility\backend\venv\Lib\site-packages\sqlalchemy\engine\default.py", line 951, in do_execute
    cursor.execute(statement, parameters)
    ~~~~~~~~~~~~~~^^^^^^^^^^^^^^^^^^^^^^^
sqlalchemy.exc.OperationalError: (sqlite3.OperationalError) no such table: tasks
[SQL: SELECT tasks.id AS tasks_id, tasks.title AS tasks_title, tasks.description AS tasks_description, tasks.status AS tasks_status, tasks.due_date AS tasks_due_date, tasks.created_at AS tasks_created_at, tasks.updated_at AS tasks_updated_at 
FROM tasks ORDER BY tasks.created_at DESC]
(Background on this error at: https://sqlalche.me/e/20/e3q8)
2025-10-22 12:27:44,062 [INFO] Registered tasks blueprint at /api/v1/tasks
2025-10-22 12:28:23,538 [INFO] GET /api/v1/tasks/ - from 127.0.0.1
2025-10-22 12:28:23,564 [INFO] GET /api/v1/tasks/ - from 127.0.0.1
2025-10-22 12:52:59,191 [INFO] Registered tasks blueprint at /api/v1/tasks
2025-10-22 12:54:19,480 [INFO] Registered tasks blueprint at /api/v1/tasks
2025-10-22 12:54:33,767 [INFO] Registered tasks blueprint at /api/v1/tasks
2025-10-22 12:54:37,974 [INFO] GET / - from 127.0.0.1
2025-10-22 12:54:40,730 [INFO] GET /favicon.ico - from 127.0.0.1
2025-10-22 12:58:06,067 [INFO] GET /api/v1/tasks/ - from 127.0.0.1
2025-10-22 12:58:06,106 [INFO] GET /api/v1/tasks/ - from 127.0.0.1
2025-10-22 12:58:10,539 [INFO] GET /api/v1/tasks/ - from 127.0.0.1
2025-10-22 12:58:10,550 [INFO] GET /api/v1/tasks/ - from 127.0.0.1
2025-10-22 12:58:40,480 [INFO] OPTIONS /api/v1/tasks - from 127.0.0.1
2025-10-22 13:01:01,720 [INFO] GET /api/v1/tasks/ - from 127.0.0.1
2025-10-22 13:02:45,161 [INFO] GET /api/v1/tasks/ - from 127.0.0.1
2025-10-22 13:02:45,272 [INFO] GET /api/v1/tasks/ - from 127.0.0.1
2025-10-22 13:02:49,858 [INFO] GET /api/v1/tasks/ - from 127.0.0.1
2025-10-22 13:02:56,007 [INFO] GET / - from 127.0.0.1
2025-10-22 13:53:56,698 [INFO] GET /api/v1/tasks - from 127.0.0.1
2025-10-22 13:54:26,950 [INFO] GET /api/v1/tasks/ - from 127.0.0.1
2025-10-22 14:15:27,583 [INFO] GET /api/v1/tasks/ - from 127.0.0.1
2025-10-22 14:15:52,535 [INFO] GET /api/v1/tasks/ - from 127.0.0.1
2025-10-22 14:15:52,545 [INFO] GET /api/v1/tasks/ - from 127.0.0.1
2025-10-22 17:52:51,112 [INFO] GET /api/v1/tasks/ - from 127.0.0.1
2025-10-22 17:52:51,343 [INFO] GET /api/v1/tasks/ - from 127.0.0.1
2025-10-22 20:36:36,764 [INFO] GET /api/v1/tasks/ - from 127.0.0.1
2025-10-22 20:36:37,028 [INFO] GET /api/v1/tasks/ - from 127.0.0.1
